Workbook

Sheet V_14
A1: CLASSIFIED TRAFFIC VOLUME COUNT AT INTERSECTION
A2: Location Name : | B2: =Summary!B2 -> TMC-14 Number (D2)
A3: Location Code : | B3: =Summary!B3 -> D2
A4: Direction From : | B4: =V_13!E4 -> Mansarover | D4: To: | E4: =V_13!B4 -> Delhi | G4: Flyover
A6: Time | B6: Car, Taxi, Tempo, Auto Rickshaw & Pick up | C6: Motar Cycle, Scooter | D6: Agriculture Tractor, LCV Mini Bus | E6: Three Wheeler (Auto) Axle Truck, Buses | F6: Tractor Trailor, Truck Trailor Units (3 Axle & MAV) | G6: Total Fast Vehicle | H6: Cycle | I6: Cycle Rickshaw | J6: Hand Cart | K6: Horse Drawn | L6: Bullock Corts | M6: Total Slow | N6: Grand Total (Nos.) | O6: Grand Total (PCU's)
A8: 0800-0815 | B8: 96 | C8: 83 | D8: 9 | E8: 10 | F8: 30 | G8: =SUM(B8:F8) -> 228 | H8: 1 | I8: 0 | J8: 0 | K8: 0 | L8: 2 | M8: 1 | N8: =G8+M8 -> 229 | O8: =B8*1+C8*0.5+D8*1.5+E8*3+F8*4.5+H8*0.5+I8*1.5+J8*3+K8*4+L8*8 -> 332.5
A9: 0815-0830 | B9: 94 | C9: 122 | D9: 9 | E9: 11 | F9: 23 | G9: =SUM(B9:F9) -> 259 | H9: 1 | I9: 0 | J9: 0 | K9: 0 | L9: 1 | M9: 0 | N9: =G9+M9 -> 259 | O9: =B9*1+C9*0.5+D9*1.5+E9*3+F9*4.5+H9*0.5+I9*1.5+J9*3+K9*4+L9*8 -> 313.5
A10: 0830-0845 | B10: 99 | C10: 167 | D10: 6 | E10: 12 | F10: 18 | G10: =SUM(B10:F10) -> 302 | H10: 0 | I10: 0 | J10: 0 | K10: 0 | L10: 2 | M10: 1 | N10: =G10+M10 -> 303 | O10: =B10*1+C10*0.5+D10*1.5+E10*3+F10*4.5+H10*0.5+I10*1.5+J10*3+K10*4+L10*8 -> 324.5
A11: 0845-0900 | B11: 111 | C11: 216 | D11: 6 | E11: 9 | F11: 28 | G11: =SUM(B11:F11) -> 370 | H11: 0 | I11: 0 | J11: 0 | K11: 0 | L11: 1 | M11: 0 | N11: =G11+M11 -> 370 | O11: =B11*1+C11*0.5+D11*1.5+E11*3+F11*4.5+H11*0.5+I11*1.5+J11*3+K11*4+L11*8 -> 389
A12: 0900-0915 | B12: 149 | C12: 195 | D12: 12 | E12: 11 | F12: 32 | G12: =SUM(B12:F12) -> 399 | H12: 1 | I12: 0 | J12: 0 | K12: 0 | L12: 4 | M12: 0 | N12: =G12+M12 -> 399 | O12: =B12*1+C12*0.5+D12*1.5+E12*3+F12*4.5+H12*0.5+I12*1.5+J12*3+K12*4+L12*8 -> 474
A13: 0915-0930 | B13: 78 | C13: 136 | D13: 8 | E13: 8 | F13: 11 | G13: =SUM(B13:F13) -> 241 | H13: 0 | I13: 0 | J13: 0 | K13: 0 | L13: 1 | M13: 0 | N13: =G13+M13 -> 241 | O13: =B13*1+C13*0.5+D13*1.5+E13*3+F13*4.5+H13*0.5+I13*1.5+J13*3+K13*4+L13*8 -> 239.5
A14: 0930-0945 | B14: 114 | C14: 178 | D14: 10 | E14: 7 | F14: 23 | G14: =SUM(B14:F14) -> 332 | H14: 0 | I14: 0 | J14: 0 | K14: 0 | L14: 1 | M14: 0 | N14: =G14+M14 -> 332 | O14: =B14*1+C14*0.5+D14*1.5+E14*3+F14*4.5+H14*0.5+I14*1.5+J14*3+K14*4+L14*8 -> 350.5
A15: 0945-1000 | B15: 130 | C15: 163 | D15: 17 | E15: 8 | F15: 18 | G15: =SUM(B15:F15) -> 336 | H15: 0 | I15: 0 | J15: 0 | K15: 0 | L15: 0 | M15: 0 | N15: =G15+M15 -> 336 | O15: =B15*1+C15*0.5+D15*1.5+E15*3+F15*4.5+H15*0.5+I15*1.5+J15*3+K15*4+L15*8 -> 342
A16: 1000-1015 | B16: 110 | C16: 140 | D16: 8 | E16: 5 | F16: 25 | G16: =SUM(B16:F16) -> 288 | H16: 0 | I16: 0 | J16: 0 | K16: 0 | L16: 0 | M16: 0 | N16: =G16+M16 -> 288 | O16: =B16*1+C16*0.5+D16*1.5+E16*3+F16*4.5+H16*0.5+I16*1.5+J16*3+K16*4+L16*8 -> 319.5
A17: 1015-1030 | B17: 158 | C17: 126 | D17: 16 | E17: 10 | F17: 21 | G17: =SUM(B17:F17) -> 331 | H17: 0 | I17: 0 | J17: 0 | K17: 0 | L17: 0 | M17: 0 | N17: =G17+M17 -> 331 | O17: =B17*1+C17*0.5+D17*1.5+E17*3+F17*4.5+H17*0.5+I17*1.5+J17*3+K17*4+L17*8 -> 369.5
A18: 1030-1045 | B18: 157 | C18: 119 | D18: 14 | E18: 11 | F18: 15 | G18: =SUM(B18:F18) -> 316 | H18: 0 | I18: 0 | J18: 0 | K18: 0 | L18: 1 | M18: 0 | N18: =G18+M18 -> 316 | O18: =B18*1+C18*0.5+D18*1.5+E18*3+F18*4.5+H18*0.5+I18*1.5+J18*3+K18*4+L18*8 -> 346
A19: 1045-1100 | B19: 145 | C19: 95 | D19: 15 | E19: 9 | F19: 26 | G19: =SUM(B19:F19) -> 290 | H19: 0 | I19: 0 | J19: 0 | K19: 0 | L19: 0 | M19: 0 | N19: =G19+M19 -> 290 | O19: =B19*1+C19*0.5+D19*1.5+E19*3+F19*4.5+H19*0.5+I19*1.5+J19*3+K19*4+L19*8 -> 359
... A103: 0745-0800 | B103: 61 | C103: 49 | D103: 15 | E103: 9 | F103: 15 | G103: =SUM(B103:F103) -> 149 | H103: 0 | I103: 0 | J103: 0 | K103: 0 | L103: 0 | M103: 0 | N103: =G103+M103 -> 149 | O103: =B103*1+C103*0.5+D103*1.5+E103*3+F103*4.5+H103*0.5+I103*1.5+J103*3+K103*4+L103*8 -> 202.5
A104: Total (Veh.) | B104: =SUM(B8:B103) -> 7091 | C104: =SUM(C8:C103) -> 5059 | D104: =SUM(D8:D103) -> 1132 | E104: =SUM(E8:E103) -> 842 | F104: =SUM(F8:F103) -> 2699 | G104: =SUM(G8:G103) -> 16823 | H104: =SUM(H8:H103) -> 4 | I104: =SUM(I8:I103) -> 0 | ... O104: =SUM(O8:O103) -> 26160
A105: Total (PCUs) | B105: =+B104*1 -> 7091 | C105: =+C104*0.5 -> 2529.5 | D105: =+D104*1.5 -> 1698 | E105: =+E104*3 -> 2526 | F105: =+F104*4.5 -> 12145.5 | G105: =SUM(B105:F105) -> 25990 | H105: =+H104*0.5 -> 2 | I105: =+I104*1.5 -> 0 | J105: =+J104*3 -> 0 | K105: =+K104*4 -> 0 | L105: =+L104*8 -> 168 | M105: =SUM(H105:L105) -> 170 | O105: =G105+M105 -> 26160
A106: Composition | B106: =B104/$N$104 -> 0.42145617 | C106: =C104/$N$104 -> 0.30068351 | D106: =D104/$N$104 -> 0.067280832 | E106: =E104/$N$104 -> 0.050044577 | F106: =F104/$N$104 -> 0.16041605 | G106: =G104/$N$104 -> 0.99988113 | H106: =H104/$N$104 -> 0.00023774146 | I106: =I104/$N$104 -> 0 | ... N106: =N104/$N$104 -> 1

Sheet V_13
A1: CLASSIFIED TRAFFIC VOLUME COUNT AT INTERSECTION
A2: Location Name : | B2: =Summary!B2 -> TMC-14 Number (D2)
A3: Location Code : | B3: =Summary!B3 -> D2
A4: Direction From : | B4: Delhi | D4: To: | E4: Mansarover | G4: Flyover
A6: Time | B6: Car, Taxi, Tempo, Auto Rickshaw & Pick up | C6: Motar Cycle, Scooter | D6: Agriculture Tractor, LCV Mini Bus | E6: Three Wheeler (Auto) Axle Truck, Buses | F6: Tractor Trailor, Truck Trailor Units (3 Axle & MAV) | G6: Total Fast Vehicle | H6: Cycle | I6: Cycle Rickshaw | J6: Hand Cart | K6: Horse Drawn | L6: Bullock Corts | M6: Total Slow | N6: Grand Total (Nos.) | O6: Grand Total (PCU's)
A8: 0800-0815 | B8: 34 | C8: 62 | D8: 18 | E8: 6 | F8: 33 | G8: =SUM(B8:F8) -> 153 | H8: 0 | I8: 0 | J8: 0 | K8: 0 | L8: 3 | M8: 0 | N8: =G8+M8 -> 153 | O8: =B8*1+C8*0.5+D8*1.5+E8*3+F8*4.5+H8*0.5+I8*1.5+J8*3+K8*4+L8*8 -> 282.5
A9: 0815-0830 | B9: 68 | C9: 89 | D9: 23 | E9: 3 | F9: 31 | G9: =SUM(B9:F9) -> 214 | H9: 0 | I9: 0 | J9: 0 | K9: 0 | L9: 1 | M9: 0 | N9: =G9+M9 -> 214 | O9: =B9*1+C9*0.5+D9*1.5+E9*3+F9*4.5+H9*0.5+I9*1.5+J9*3+K9*4+L9*8 -> 303.5
A10: 0830-0845 | B10: 78 | C10: 110 | D10: 19 | E10: 5 | F10: 26 | G10: =SUM(B10:F10) -> 238 | H10: 0 | I10: 0 | J10: 0 | K10: 0 | L10: 1 | M10: 0 | N10: =G10+M10 -> 238 | O10: =B10*1+C10*0.5+D10*1.5+E10*3+F10*4.5+H10*0.5+I10*1.5+J10*3+K10*4+L10*8 -> 301.5
A11: 0845-0900 | B11: 78 | C11: 115 | D11: 16 | E11: 3 | F11: 21 | G11: =SUM(B11:F11) -> 233 | H11: 0 | I11: 0 | J11: 0 | K11: 0 | L11: 0 | M11: 0 | N11: =G11+M11 -> 233 | O11: =B11*1+C11*0.5+D11*1.5+E11*3+F11*4.5+H11*0.5+I11*1.5+J11*3+K11*4+L11*8 -> 263
A12: 0900-0915 | B12: 85 | C12: 122 | D12: 12 | E12: 4 | F12: 33 | G12: =SUM(B12:F12) -> 256 | H12: 0 | I12: 0 | J12: 0 | K12: 0 | L12: 0 | M12: 0 | N12: =G12+M12 -> 256 | O12: =B12*1+C12*0.5+D12*1.5+E12*3+F12*4.5+H12*0.5+I12*1.5+J12*3+K12*4+L12*8 -> 324.5
A13: 0915-0930 | B13: 52 | C13: 107 | D13: 13 | E13: 6 | F13: 13 | G13: =SUM(B13:F13) -> 191 | H13: 0 | I13: 0 | J13: 0 | K13: 0 | L13: 1 | M13: 0 | N13: =G13+M13 -> 191 | O13: =B13*1+C13*0.5+D13*1.5+E13*3+F13*4.5+H13*0.5+I13*1.5+J13*3+K13*4+L13*8 -> 209.5
A14: 0930-0945 | B14: 120 | C14: 142 | D14: 29 | E14: 10 | F14: 23 | G14: =SUM(B14:F14) -> 324 | H14: 0 | I14: 0 | J14: 0 | K14: 0 | L14: 1 | M14: 0 | N14: =G14+M14 -> 324 | O14: =B14*1+C14*0.5+D14*1.5+E14*3+F14*4.5+H14*0.5+I14*1.5+J14*3+K14*4+L14*8 -> 376
A15: 0945-1000 | B15: 81 | C15: 107 | D15: 28 | E15: 3 | F15: 21 | G15: =SUM(B15:F15) -> 240 | H15: 0 | I15: 0 | J15: 0 | K15: 0 | L15: 0 | M15: 0 | N15: =G15+M15 -> 240 | O15: =B15*1+C15*0.5+D15*1.5+E15*3+F15*4.5+H15*0.5+I15*1.5+J15*3+K15*4+L15*8 -> 280
A16: 1000-1015 | B16: 83 | C16: 116 | D16: 25 | E16: 4 | F16: 22 | G16: =SUM(B16:F16) -> 250 | H16: 0 | I16: 0 | J16: 0 | K16: 0 | L16: 1 | M16: 0 | N16: =G16+M16 -> 250 | O16: =B16*1+C16*0.5+D16*1.5+E16*3+F16*4.5+H16*0.5+I16*1.5+J16*3+K16*4+L16*8 -> 297.5
A17: 1015-1030 | B17: 97 | C17: 110 | D17: 22 | E17: 7 | F17: 28 | G17: =SUM(B17:F17) -> 264 | H17: 0 | I17: 0 | J17: 0 | K17: 0 | L17: 0 | M17: 0 | N17: =G17+M17 -> 264 | O17: =B17*1+C17*0.5+D17*1.5+E17*3+F17*4.5+H17*0.5+I17*1.5+J17*3+K17*4+L17*8 -> 332
A18: 1030-1045 | B18: 135 | C18: 61 | D18: 32 | E18: 5 | F18: 28 | G18: =SUM(B18:F18) -> 261 | H18: 0 | I18: 0 | J18: 0 | K18: 0 | L18: 1 | M18: 0 | N18: =G18+M18 -> 261 | O18: =B18*1+C18*0.5+D18*1.5+E18*3+F18*4.5+H18*0.5+I18*1.5+J18*3+K18*4+L18*8 -> 362.5
A19: 1045-1100 | B19: 109 | C19: 77 | D19: 23 | E19: 4 | F19: 22 | G19: =SUM(B19:F19) -> 235 | H19: 0 | I19: 0 | J19: 0 | K19: 0 | L19: 0 | M19: 0 | N19: =G19+M19 -> 235 | O19: =B19*1+C19*0.5+D19*1.5+E19*3+F19*4.5+H19*0.5+I19*1.5+J19*3+K19*4+L19*8 -> 293
... A103: 0745-0800 | B103: 31 | C103: 32 | D103: 12 | E103: 2 | F103: 13 | G103: =SUM(B103:F103) -> 90 | H103: 0 | I103: 0 | J103: 0 | K103: 0 | L103: 0 | M103: 0 | N103: =G103+M103 -> 90 | O103: =B103*1+C103*0.5+D103*1.5+E103*3+F103*4.5+H103*0.5+I103*1.5+J103*3+K103*4+L103*8 -> 129.5
A104: Total (Veh.) | B104: =SUM(B8:B103) -> 6894 | C104: =SUM(C8:C103) -> 4001 | D104: =SUM(D8:D103) -> 1471 | E104: =SUM(E8:E103) -> 440 | F104: =SUM(F8:F103) -> 2689 | G104: =SUM(G8:G103) -> 15495 | H104: =SUM(H8:H103) -> 2 | I104: =SUM(I8:I103) -> 0 | ... O104: =SUM(O8:O103) -> 24650.5
A105: Total (PCUs) | B105: =+B104*1 -> 6894 | C105: =+C104*0.5 -> 2000.5 | D105: =+D104*1.5 -> 2206.5 | E105: =+E104*3 -> 1320 | F105: =+F104*4.5 -> 12100.5 | G105: =SUM(B105:F105) -> 24521.5 | H105: =+H104*0.5 -> 1 | I105: =+I104*1.5 -> 0 | J105: =+J104*3 -> 0 | K105: =+K104*4 -> 0 | L105: =+L104*8 -> 128 | M105: =SUM(H105:L105) -> 129 | O105: =G105+M105 -> 24650.5
A106: Composition | B106: =B104/$N$104 -> 0.44491772 | C106: =C104/$N$104 -> 0.25821233 | D106: =D104/$N$104 -> 0.09493385 | E106: =E104/$N$104 -> 0.028396257 | F106: =F104/$N$104 -> 0.17353985 | G106: =G104/$N$104 -> 1 | H106: =H104/$N$104 -> 0.00012907389 | I106: =I104/$N$104 -> 0 | ... N106: =N104/$N$104 -> 1

Sheet Summary
H1: Date: | I1: 46245
A2: Location Name: | B2: TMC-14 Number (D2) | H2: Day: | I2: =IF(WEEKDAY(I1,2)=1,"Monday",IF(WEEKDAY(I1,2)=2,"Tuesday",IF(WEEKDAY(I1,2)=3,"Wednesday",IF(WEEKDAY(I1,2)=4,"Thursday",IF(WEEKDAY(I1,2)=5,"Friday","Saturday"))))) -> Tuesday
A3: Location Code: | B3: D2
A5: Approach | B5: Left | C5: Straight | D5: Right
A6: Nindar | B6: =A7 -> Delhi | C6: =A8 -> Chomu Pulia | D6: =A9 -> Mansarover | H6: =A6 -> Nindar
A7: Delhi | B7: =A8 -> Chomu Pulia | C7: =A9 -> Mansarover | D7: =A6 -> Nindar
A8: Chomu Pulia | B8: =A9 -> Mansarover | C8: =A6 -> Nindar | D8: =A7 -> Delhi
A9: Mansarover | B9: =A6 -> Nindar | C9: =A7 -> Delhi | D9: =A8 -> Chomu Pulia | H9: V3 V2 V1
G10: V10 | I10: V6
F11: =A9 -> Mansarover | G11: V11 | I11: V5 | J11: =A7 -> Delhi
G12: V12 | I12: V4
H13: V7 V8 V9
H16: =A8 -> Chomu Pulia

Sheet V_1
A1: CLASSIFIED TRAFFIC VOLUME COUNT AT INTERSECTION
A2: Location Name : | B2: =Summary!B2 -> TMC-14 Number (D2)
A3: Location Code : | B3: =Summary!B3 -> D2
A4: Direction From : | B4: =+Summary!A6 -> Nindar | D4: To: | E4: =Summary!J11 -> Delhi
A6: Time | B6: Car, Taxi, Tempo, Auto Rickshaw & Pick up | C6: Motar Cycle, Scooter | D6: Agriculture Tractor, LCV Mini Bus | E6: Three Wheeler (Auto) Axle Truck, Buses | F6: Tractor Trailor, Truck Trailor Units (3 Axle & MAV) | G6: Total Fast Vehicle | H6: Cycle | I6: Cycle Rickshaw | J6: Hand Cart | K6: Horse Drawn | L6: Bullock Corts | M6: Total Slow | N6: Grand Total (Nos.) | O6: Grand Total (PCU's)
A8: 0800-0815 | B8: 6 | C8: 35 | D8: 1 | E8: 1 | F8: 0 | G8: =SUM(B8:F8) -> 43 | H8: 0 | I8: 0 | J8: 0 | K8: 0 | L8: 1 | M8: 0 | N8: =G8+M8 -> 43 | O8: =B8*1+C8*0.5+D8*1.5+E8*3+F8*4.5+H8*0.5+I8*1.5+J8*3+K8*4+L8*8 -> 36
A9: 0815-0830 | B9: 6 | C9: 37 | D9: 1 | E9: 0 | F9: 0 | G9: =SUM(B9:F9) -> 44 | H9: 0 | I9: 0 | J9: 0 | K9: 0 | L9: 0 | M9: 0 | N9: =G9+M9 -> 44 | O9: =B9*1+C9*0.5+D9*1.5+E9*3+F9*4.5+H9*0.5+I9*1.5+J9*3+K9*4+L9*8 -> 26
A10: 0830-0845 | B10: 14 | C10: 62 | D10: 0 | E10: 0 | F10: 0 | G10: =SUM(B10:F10) -> 76 | H10: 0 | I10: 0 | J10: 0 | K10: 0 | L10: 1 | M10: 0 | N10: =G10+M10 -> 76 | O10: =B10*1+C10*0.5+D10*1.5+E10*3+F10*4.5+H10*0.5+I10*1.5+J10*3+K10*4+L10*8 -> 53
A11: 0845-0900 | B11: 11 | C11: 69 | D11: 0 | E11: 0 | F11: 0 | G11: =SUM(B11:F11) -> 80 | H11: 0 | I11: 0 | J11: 0 | K11: 0 | L11: 1 | M11: 0 | N11: =G11+M11 -> 80 | O11: =B11*1+C11*0.5+D11*1.5+E11*3+F11*4.5+H11*0.5+I11*1.5+J11*3+K11*4+L11*8 -> 53.5
A12: 0900-0915 | B12: 9 | C12: 60 | D12: 1 | E12: 0 | F12: 1 | G12: =SUM(B12:F12) -> 71 | H12: 0 | I12: 0 | J12: 0 | K12: 0 | L12: 1 | M12: 0 | N12: =G12+M12 -> 71 | O12: =B12*1+C12*0.5+D12*1.5+E12*3+F12*4.5+H12*0.5+I12*1.5+J12*3+K12*4+L12*8 -> 53
A13: 0915-0930 | B13: 21 | C13: 72 | D13: 0 | E13: 0 | F13: 0 | G13: =SUM(B13:F13) -> 93 | H13: 0 | I13: 0 | J13: 0 | K13: 0 | L13: 0 | M13: 0 | N13: =G13+M13 -> 93 | O13: =B13*1+C13*0.5+D13*1.5+E13*3+F13*4.5+H13*0.5+I13*1.5+J13*3+K13*4+L13*8 -> 57
A14: 0930-0945 | B14: 21 | C14: 78 | D14: 1 | E14: 0 | F14: 0 | G14: =SUM(B14:F14) -> 100 | H14: 0 | I14: 0 | J14: 0 | K14: 0 | L14: 1 | M14: 0 | N14: =G14+M14 -> 100 | O14: =B14*1+C14*0.5+D14*1.5+E14*3+F14*4.5+H14*0.5+I14*1.5+J14*3+K14*4+L14*8 -> 69.5
A15: 0945-1000 | B15: 29 | C15: 73 | D15: 1 | E15: 0 | F15: 2 | G15: =SUM(B15:F15) -> 105 | H15: 0 | I15: 0 | J15: 0 | K15: 0 | L15: 1 | M15: 0 | N15: =G15+M15 -> 105 | O15: =B15*1+C15*0.5+D15*1.5+E15*3+F15*4.5+H15*0.5+I15*1.5+J15*3+K15*4+L15*8 -> 84
A16: 1000-1015 | B16: 26 | C16: 60 | D16: 2 | E16: 0 | F16: 5 | G16: =SUM(B16:F16) -> 93 | H16: 1 | I16: 0 | J16: 0 | K16: 0 | L16: 2 | M16: 0 | N16: =G16+M16 -> 93 | O16: =B16*1+C16*0.5+D16*1.5+E16*3+F16*4.5+H16*0.5+I16*1.5+J16*3+K16*4+L16*8 -> 98
A17: 1015-1030 | B17: 27 | C17: 48 | D17: 1 | E17: 1 | F17: 1 | G17: =SUM(B17:F17) -> 78 | H17: 0 | I17: 0 | J17: 0 | K17: 0 | L17: 0 | M17: 0 | N17: =G17+M17 -> 78 | O17: =B17*1+C17*0.5+D17*1.5+E17*3+F17*4.5+H17*0.5+I17*1.5+J17*3+K17*4+L17*8 -> 60
A18: 1030-1045 | B18: 28 | C18: 49 | D18: 3 | E18: 0 | F18: 1 | G18: =SUM(B18:F18) -> 81 | H18: 0 | I18: 0 | J18: 0 | K18: 0 | L18: 0 | M18: 0 | N18: =G18+M18 -> 81 | O18: =B18*1+C18*0.5+D18*1.5+E18*3+F18*4.5+H18*0.5+I18*1.5+J18*3+K18*4+L18*8 -> 61.5
A19: 1045-1100 | B19: 28 | C19: 51 | D19: 3 | E19: 0 | F19: 1 | G19: =SUM(B19:F19) -> 83 | H19: 0 | I19: 0 | J19: 0 | K19: 0 | L19: 1 | M19: 0 | N19: =G19+M19 -> 83 | O19: =B19*1+C19*0.5+D19*1.5+E19*3+F19*4.5+H19*0.5+I19*1.5+J19*3+K19*4+L19*8 -> 70.5
... A103: 0745-0800 | B103: 11 | C103: 30 | D103: 1 | E103: 0 | F103: 0 | G103: =SUM(B103:F103) -> 42 | H103: 0 | I103: 0 | J103: 0 | K103: 0 | L103: 0 | M103: 0 | N103: =G103+M103 -> 42 | O103: =B103*1+C103*0.5+D103*1.5+E103*3+F103*4.5+H103*0.5+I103*1.5+J103*3+K103*4+L103*8 -> 27.5
A104: Total (Veh.) | B104: =SUM(B8:B103) -> 1129 | C104: =SUM(C8:C103) -> 1682 | D104: =SUM(D8:D103) -> 126 | E104: =SUM(E8:E103) -> 37 | F104: =SUM(F8:F103) -> 66 | G104: =SUM(G8:G103) -> 3040 | H104: =SUM(H8:H103) -> 3 | I104: =SUM(I8:I103) -> 1 | ... O104: =SUM(O8:O103) -> 2794
A105: Total (PCUs) | B105: =+B104*1 -> 1129 | C105: =+C104*0.5 -> 841 | D105: =+D104*1.5 -> 189 | E105: =+E104*3 -> 111 | F105: =+F104*4.5 -> 297 | G105: =SUM(B105:F105) -> 2567 | H105: =+H104*0.5 -> 1.5 | I105: =+I104*1.5 -> 1.5 | J105: =+J104*3 -> 0 | K105: =+K104*4 -> 0 | L105: =+L104*8 -> 224 | M105: =SUM(H105:L105) -> 227 | O105: =G105+M105 -> 2794
A106: Composition | B106: =B104/$N$104 -> 0.37113741 | C106: =C104/$N$104 -> 0.55292571 | D106: =D104/$N$104 -> 0.041420118 | E106: =E104/$N$104 -> 0.012163051 | F106: =F104/$N$104 -> 0.021696252 | G106: =G104/$N$104 -> 0.99934254 | H106: =H104/$N$104 -> 0.00098619329 | I106: =I104/$N$104 -> 0.0003287311 | ... N106: =N104/$N$104 -> 1
A108: Location Name : | B108: =B2 -> TMC-14 Number (D2)
A109: Location Code : | B109: =B3 -> D2
A110: Direction From : | B110: =B4 -> Nindar | D110: =D4 -> To:
A112: Time | B112: Car, Taxi, Tempo, Auto Rickshaw & Pick up | C112: Motar Cycle, Scooter | D112: Agriculture Tractor, LCV Mini Bus | E112: Three Wheeler (Auto) Axle Truck, Buses | F112: Tractor Trailor, Truck Trailor Units (3 Axle & MAV) | G112: Total Fast Vehicle | H112: Cycle | I112: Cycle Rickshaw | J112: Hand Cart | K112: Horse Drawn | L112: Bullock Corts | M112: Total Slow | N112: Grand Total (Nos.) | O112: Grand Total (PCU's)
A114: 0800 - 0900 | B114: =B8+B9+B10+B11 -> 37 | C114: =C8+C9+C10+C11 -> 203 | D114: =D8+D9+D10+D11 -> 2 | E114: =E8+E9+E10+E11 -> 1 | F114: =F8+F9+F10+F11 -> 0 | G114: =SUM(B114:F114) -> 243 | H114: =H8+H9+H10+H11 -> 0 | I114: =I8+I9+I10+I11 -> 0 | J114: =J8+J9+J10+J11 -> 0 | K114: =K8+K9+K10+K11 -> 0 | L114: =L8+L9+L10+L11 -> 3 | M114: =SUM(H114:K114) -> 0 | N114: =G114+M114 -> 243 | O114: =B114*1+C114*0.5+D114*1.5+E114*3+F114*4.5+H114*0.5+I114*1.5+J114*3+K114*4+L114*8 -> 168.5
A115: 0815 - 0915 | B115: =B9+B10+B11+B12 -> 40 | C115: =C9+C10+C11+C12 -> 228 | D115: =D9+D10+D11+D12 -> 2 | E115: =E9+E10+E11+E12 -> 0 | F115: =F9+F10+F11+F12 -> 1 | G115: =SUM(B115:F115) -> 271 | H115: =H9+H10+H11+H12 -> 0 | I115: =I9+I10+I11+I12 -> 0 | J115: =J9+J10+J11+J12 -> 0 | K115: =K9+K10+K11+K12 -> 0 | L115: =L9+L10+L11+L12 -> 3 | M115: =SUM(H115:K115) -> 0 | N115: =G115+M115 -> 271 | O115: =B115*1+C115*0.5+D115*1.5+E115*3+F115*4.5+H115*0.5+I115*1.5+J115*3+K115*4+L115*8 -> 185.5
A116: 0830 - 0930 | B116: =B10+B11+B12+B13 -> 55 | C116: =C10+C11+C12+C13 -> 263 | D116: =D10+D11+D12+D13 -> 1 | E116: =E10+E11+E12+E13 -> 0 | F116: =F10+F11+F12+F13 -> 1 | G116: =SUM(B116:F116) -> 320 | H116: =H10+H11+H12+H13 -> 0 | I116: =I10+I11+I12+I13 -> 0 | J116: =J10+J11+J12+J13 -> 0 | K116: =K10+K11+K12+K13 -> 0 | L116: =L10+L11+L12+L13 -> 3 | M116: =SUM(H116:K116) -> 0 | N116: =G116+M116 -> 320 | O116: =B116*1+C116*0.5+D116*1.5+E116*3+F116*4.5+H116*0.5+I116*1.5+J116*3+K116*4+L116*8 -> 216.5
A117: 0845 - 0945 | B117: =B11+B12+B13+B14 -> 62 | C117: =C11+C12+C13+C14 -> 279 | D117: =D11+D12+D13+D14 -> 2 | E117: =E11+E12+E13+E14 -> 0 | F117: =F11+F12+F13+F14 -> 1 | G117: =SUM(B117:F117) -> 344 | H117: =H11+H12+H13+H14 -> 0 | I117: =I11+I12+I13+I14 -> 0 | J117: =J11+J12+J13+J14 -> 0 | K117: =K11+K12+K13+K14 -> 0 | L117: =L11+L12+L13+L14 -> 3 | M117: =SUM(H117:K117) -> 0 | N117: =G117+M117 -> 344 | O117: =B117*1+C117*0.5+D117*1.5+E117*3+F117*4.5+H117*0.5+I117*1.5+J117*3+K117*4+L117*8 -> 233
A118: 0900 - 1000 | B118: =B12+B13+B14+B15 -> 80 | C118: =C12+C13+C14+C15 -> 283 | D118: =D12+D13+D14+D15 -> 3 | E118: =E12+E13+E14+E15 -> 0 | F118: =F12+F13+F14+F15 -> 3 | G118: =SUM(B118:F118) -> 369 | H118: =H12+H13+H14+H15 -> 0 | I118: =I12+I13+I14+I15 -> 0 | J118: =J12+J13+J14+J15 -> 0 | K118: =K12+K13+K14+K15 -> 0 | L118: =L12+L13+L14+L15 -> 3 | M118: =SUM(H118:K118) -> 0 | N118: =G118+M118 -> 369 | O118: =B118*1+C118*0.5+D118*1.5+E118*3+F118*4.5+H118*0.5+I118*1.5+J118*3+K118*4+L118*8 -> 263.5
A119: 0915 - 1015 | B119: =B13+B14+B15+B16 -> 97 | C119: =C13+C14+C15+C16 -> 283 | D119: =D13+D14+D15+D16 -> 4 | E119: =E13+E14+E15+E16 -> 0 | F119: =F13+F14+F15+F16 -> 7 | G119: =SUM(B119:F119) -> 391 | H119: =H13+H14+H15+H16 -> 1 | I119: =I13+I14+I15+I16 -> 0 | J119: =J13+J14+J15+J16 -> 0 | K119: =K13+K14+K15+K16 -> 0 | L119: =L13+L14+L15+L16 -> 4 | M119: =SUM(H119:K119) -> 1 | N119: =G119+M119 -> 392 | O119: =B119*1+C119*0.5+D119*1.5+E119*3+F119*4.5+H119*0.5+I119*1.5+J119*3+K119*4+L119*8 -> 308.5
A120: 0930 - 1030 | B120: =B14+B15+B16+B17 -> 103 | C120: =C14+C15+C16+C17 -> 259 | D120: =D14+D15+D16+D17 -> 5 | E120: =E14+E15+E16+E17 -> 1 | F120: =F14+F15+F16+F17 -> 8 | G120: =SUM(B120:F120) -> 376 | H120: =H14+H15+H16+H17 -> 1 | I120: =I14+I15+I16+I17 -> 0 | J120: =J14+J15+J16+J17 -> 0 | K120: =K14+K15+K16+K17 -> 0 | L120: =L14+L15+L16+L17 -> 4 | M120: =SUM(H120:K120) -> 1 | N120: =G120+M120 -> 377 | O120: =B120*1+C120*0.5+D120*1.5+E120*3+F120*4.5+H120*0.5+I120*1.5+J120*3+K120*4+L120*8 -> 311.5
A121: 0945 - 1045 | B121: =B15+B16+B17+B18 -> 110 | C121: =C15+C16+C17+C18 -> 230 | D121: =D15+D16+D17+D18 -> 7 | E121: =E15+E16+E17+E18 -> 1 | F121: =F15+F16+F17+F18 -> 9 | G121: =SUM(B121:F121) -> 357 | H121: =H15+H16+H17+H18 -> 1 | I121: =I15+I16+I17+I18 -> 0 | J121: =J15+J16+J17+J18 -> 0 | K121: =K15+K16+K17+K18 -> 0 | L121: =L15+L16+L17+L18 -> 3 | M121: =SUM(H121:K121) -> 1 | N121: =G121+M121 -> 358 | O121: =B121*1+C121*0.5+D121*1.5+E121*3+F121*4.5+H121*0.5+I121*1.5+J121*3+K121*4+L121*8 -> 303.5
A122: 1000 - 1100 | B122: =B16+B17+B18+B19 -> 109 | C122: =C16+C17+C18+C19 -> 208 | D122: =D16+D17+D18+D19 -> 9 | E122: =E16+E17+E18+E19 -> 1 | F122: =F16+F17+F18+F19 -> 8 | G122: =SUM(B122:F122) -> 335 | H122: =H16+H17+H18+H19 -> 1 | I122: =I16+I17+I18+I19 -> 0 | J122: =J16+J17+J18+J19 -> 0 | K122: =K16+K17+K18+K19 -> 0 | L122: =L16+L17+L18+L19 -> 3 | M122: =SUM(H122:K122) -> 1 | N122: =G122+M122 -> 336 | O122: =B122*1+C122*0.5+D122*1.5+E122*3+F122*4.5+H122*0.5+I122*1.5+J122*3+K122*4+L122*8 -> 290
A123: 1015 - 1115 | B123: =B17+B18+B19+B20 -> 112 | C123: =C17+C18+C19+C20 -> 195 | D123: =D17+D18+D19+D20 -> 8 | E123: =E17+E18+E19+E20 -> 2 | F123: =F17+F18+F19+F20 -> 3 | G123: =SUM(B123:F123) -> 320 | H123: =H17+H18+H19+H20 -> 0 | I123: =I17+I18+I19+I20 -> 0 | J123: =J17+J18+J19+J20 -> 0 | K123: =K17+K18+K19+K20 -> 0 | L123: =L17+L18+L19+L20 -> 2 | M123: =SUM(H123:K123) -> 0 | N123: =G123+M123 -> 320 | O123: =B123*1+C123*0.5+D123*1.5+E123*3+F123*4.5+H123*0.5+I123*1.5+J123*3+K123*4+L123*8 -> 257
A124: 1030 - 1130 | B124: =B18+B19+B20+B21 -> 111 | C124: =C18+C19+C20+C21 -> 196 | D124: =D18+D19+D20+D21 -> 12 | E124: =E18+E19+E20+E21 -> 3 | F124: =F18+F19+F20+F21 -> 3 | G124: =SUM(B124:F124) -> 325 | H124: =H18+H19+H20+H21 -> 0 | I124: =I18+I19+I20+I21 -> 0 | J124: =J18+J19+J20+J21 -> 0 | K124: =K18+K19+K20+K21 -> 0 | L124: =L18+L19+L20+L21 -> 2 | M124: =SUM(H124:K124) -> 0 | N124: =G124+M124 -> 325 | O124: =B124*1+C124*0.5+D124*1.5+E124*3+F124*4.5+H124*0.5+I124*1.5+J124*3+K124*4+L124*8 -> 265.5
A125: 1045 - 1145 | B125: =B19+B20+B21+B22 -> 106 | C125: =C19+C20+C21+C22 -> 183 | D125: =D19+D20+D21+D22 -> 10 | E125: =E19+E20+E21+E22 -> 3 | F125: =F19+F20+F21+F22 -> 2 | G125: =SUM(B125:F125) -> 304 | H125: =H19+H20+H21+H22 -> 0 | I125: =I19+I20+I21+I22 -> 1 | J125: =J19+J20+J21+J22 -> 0 | K125: =K19+K20+K21+K22 -> 0 | L125: =L19+L20+L21+L22 -> 2 | M125: =SUM(H125:K125) -> 1 | N125: =G125+M125 -> 305 | O125: =B125*1+C125*0.5+D125*1.5+E125*3+F125*4.5+H125*0.5+I125*1.5+J125*3+K125*4+L125*8 -> 248
... A206: 0745 - 0845 | B206: =B100+B101+B102+B103 -> 31 | C206: =C100+C101+C102+C103 -> 92 | D206: =D100+D101+D102+D103 -> 2 | E206: =E100+E101+E102+E103 -> 0 | F206: =F100+F101+F102+F103 -> 0 | G206: =SUM(B206:F206) -> 125 | H206: =H100+H101+H102+H103 -> 0 | I206: =I100+I101+I102+I103 -> 0 | J206: =J100+J101+J102+J103 -> 0 | K206: =K100+K101+K102+K103 -> 0 | L206: =L100+L101+L102+L103 -> 0 | M206: =SUM(H206:K206) -> 0 | N206: =G206+M206 -> 125 | O206: =B206*1+C206*0.5+D206*1.5+E206*3+F206*4.5+H206*0.5+I206*1.5+J206*3+K206*4+L206*8 -> 80

Sheet V_2
A1: CLASSIFIED TRAFFIC VOLUME COUNT AT INTERSECTION
A2: Location Name : | B2: =Summary!B2 -> TMC-14 Number (D2)
A3: Location Code : | B3: =Summary!B3 -> D2
A4: Direction From : | B4: =+Summary!A6 -> Nindar | D4: To: | E4: =Summary!H16 -> Chomu Pulia
A6: Time | B6: Car, Taxi, Tempo, Auto Rickshaw & Pick up | C6: Motar Cycle, Scooter | D6: Agriculture Tractor, LCV Mini Bus | E6: Three Wheeler (Auto) Axle Truck, Buses | F6: Tractor Trailor, Truck Trailor Units (3 Axle & MAV) | G6: Total Fast Vehicle | H6: Cycle | I6: Cycle Rickshaw | J6: Hand Cart | K6: Horse Drawn | L6: Bullock Corts | M6: Total Slow | N6: Grand Total (Nos.) | O6: Grand Total (PCU's)
A8: 0800-0815 | B8: 167 | C8: 176 | D8: 4 | E8: 8 | F8: 2 | G8: =SUM(B8:F8) -> 357 | H8: 2 | I8: 0 | J8: 0 | K8: 0 | L8: 6 | M8: 0 | N8: =G8+M8 -> 357 | O8: =B8*1+C8*0.5+D8*1.5+E8*3+F8*4.5+H8*0.5+I8*1.5+J8*3+K8*4+L8*8 -> 343
A9: 0815-0830 | B9: 183 | C9: 187 | D9: 2 | E9: 7 | F9: 0 | G9: =SUM(B9:F9) -> 379 | H9: 0 | I9: 0 | J9: 0 | K9: 0 | L9: 2 | M9: 0 | N9: =G9+M9 -> 379 | O9: =B9*1+C9*0.5+D9*1.5+E9*3+F9*4.5+H9*0.5+I9*1.5+J9*3+K9*4+L9*8 -> 316.5
A10: 0830-0845 | B10: 168 | C10: 157 | D10: 1 | E10: 14 | F10: 8 | G10: =SUM(B10:F10) -> 348 | H10: 0 | I10: 0 | J10: 0 | K10: 0 | L10: 1 | M10: 0 | N10: =G10+M10 -> 348 | O10: =B10*1+C10*0.5+D10*1.5+E10*3+F10*4.5+H10*0.5+I10*1.5+J10*3+K10*4+L10*8 -> 334
A11: 0845-0900 | B11: 104 | C11: 128 | D11: 1 | E11: 5 | F11: 0 | G11: =SUM(B11:F11) -> 238 | H11: 0 | I11: 0 | J11: 0 | K11: 0 | L11: 4 | M11: 0 | N11: =G11+M11 -> 238 | O11: =B11*1+C11*0.5+D11*1.5+E11*3+F11*4.5+H11*0.5+I11*1.5+J11*3+K11*4+L11*8 -> 216.5
A12: 0900-0915 | B12: 135 | C12: 157 | D12: 0 | E12: 8 | F12: 0 | G12: =SUM(B12:F12) -> 300 | H12: 0 | I12: 0 | J12: 0 | K12: 0 | L12: 4 | M12: 0 | N12: =G12+M12 -> 300 | O12: =B12*1+C12*0.5+D12*1.5+E12*3+F12*4.5+H12*0.5+I12*1.5+J12*3+K12*4+L12*8 -> 269.5
A13: 0915-0930 | B13: 143 | C13: 166 | D13: 3 | E13: 5 | F13: 0 | G13: =SUM(B13:F13) -> 317 | H13: 0 | I13: 0 | J13: 0 | K13: 0 | L13: 1 | M13: 0 | N13: =G13+M13 -> 317 | O13: =B13*1+C13*0.5+D13*1.5+E13*3+F13*4.5+H13*0.5+I13*1.5+J13*3+K13*4+L13*8 -> 253.5
A14: 0930-0945 | B14: 167 | C14: 210 | D14: 5 | E14: 9 | F14: 2 | G14: =SUM(B14:F14) -> 393 | H14: 0 | I14: 0 | J14: 0 | K14: 0 | L14: 4 | M14: 1 | N14: =G14+M14 -> 394 | O14: =B14*1+C14*0.5+D14*1.5+E14*3+F14*4.5+H14*0.5+I14*1.5+J14*3+K14*4+L14*8 -> 347.5
A15: 0945-1000 | B15: 181 | C15: 160 | D15: 6 | E15: 20 | F15: 1 | G15: =SUM(B15:F15) -> 368 | H15: 0 | I15: 0 | J15: 0 | K15: 0 | L15: 1 | M15: 0 | N15: =G15+M15 -> 368 | O15: =B15*1+C15*0.5+D15*1.5+E15*3+F15*4.5+H15*0.5+I15*1.5+J15*3+K15*4+L15*8 -> 342.5
A16: 1000-1015 | B16: 167 | C16: 132 | D16: 6 | E16: 18 | F16: 4 | G16: =SUM(B16:F16) -> 327 | H16: 0 | I16: 0 | J16: 0 | K16: 0 | L16: 1 | M16: 0 | N16: =G16+M16 -> 327 | O16: =B16*1+C16*0.5+D16*1.5+E16*3+F16*4.5+H16*0.5+I16*1.5+J16*3+K16*4+L16*8 -> 322
A17: 1015-1030 | B17: 192 | C17: 126 | D17: 8 | E17: 14 | F17: 5 | G17: =SUM(B17:F17) -> 345 | H17: 0 | I17: 0 | J17: 0 | K17: 0 | L17: 0 | M17: 0 | N17: =G17+M17 -> 345 | O17: =B17*1+C17*0.5+D17*1.5+E17*3+F17*4.5+H17*0.5+I17*1.5+J17*3+K17*4+L17*8 -> 331.5
A18: 1030-1045 | B18: 134 | C18: 33 | D18: 3 | E18: 18 | F18: 5 | G18: =SUM(B18:F18) -> 193 | H18: 0 | I18: 0 | J18: 0 | K18: 0 | L18: 0 | M18: 0 | N18: =G18+M18 -> 193 | O18: =B18*1+C18*0.5+D18*1.5+E18*3+F18*4.5+H18*0.5+I18*1.5+J18*3+K18*4+L18*8 -> 231.5
A19: 1045-1100 | B19: 144 | C19: 47 | D19: 4 | E19: 10 | F19: 2 | G19: =SUM(B19:F19) -> 207 | H19: 0 | I19: 0 | J19: 0 | K19: 0 | L19: 2 | M19: 0 | N19: =G19+M19 -> 207 | O19: =B19*1+C19*0.5+D19*1.5+E19*3+F19*4.5+H19*0.5+I19*1.5+J19*3+K19*4+L19*8 -> 228.5
... A103: 0745-0800 | B103: 290 | C103: 575 | D103: 3 | E103: 9 | F103: 2 | G103: =SUM(B103:F103) -> 879 | H103: 3 | I103: 0 | J103: 0 | K103: 0 | L103: 3 | M103: 0 | N103: =G103+M103 -> 879 | O103: =B103*1+C103*0.5+D103*1.5+E103*3+F103*4.5+H103*0.5+I103*1.5+J103*3+K103*4+L103*8 -> 643.5
A104: Total (Veh.) | B104: =SUM(B8:B103) -> 8964 | C104: =SUM(C8:C103) -> 7500 | D104: =SUM(D8:D103) -> 293 | E104: =SUM(E8:E103) -> 617 | F104: =SUM(F8:F103) -> 147 | G104: =SUM(G8:G103) -> 17521 | H104: =SUM(H8:H103) -> 19 | I104: =SUM(I8:I103) -> 0 | ... O104: =SUM(O8:O103) -> 16243.5
A105: Total (PCUs) | B105: =+B104*1 -> 8964 | C105: =+C104*0.5 -> 3750 | D105: =+D104*1.5 -> 439.5 | E105: =+E104*3 -> 1851 | F105: =+F104*4.5 -> 661.5 | G105: =SUM(B105:F105) -> 15666 | H105: =+H104*0.5 -> 9.5 | I105: =+I104*1.5 -> 0 | J105: =+J104*3 -> 0 | K105: =+K104*4 -> 0 | L105: =+L104*8 -> 568 | M105: =SUM(H105:L105) -> 577.5 | O105: =G105+M105 -> 16243.5
A106: Composition | B106: =B104/$N$104 -> 0.51143949 | C106: =C104/$N$104 -> 0.42791122 | D106: =D104/$N$104 -> 0.016717065 | E106: =E104/$N$104 -> 0.03520283 | F106: =F104/$N$104 -> 0.00838706 | G106: =G104/$N$104 -> 0.99965767 | H106: =H104/$N$104 -> 0.0010840418 | I106: =I104/$N$104 -> 0 | ... N106: =N104/$N$104 -> 1
A108: Location Name : | B108: =B2 -> TMC-14 Number (D2)
A109: Location Code : | B109: =B3 -> D2
A110: Direction From : | B110: =B4 -> Nindar | D110: =D4 -> To:
A112: Time | B112: Car, Taxi, Tempo, Auto Rickshaw & Pick up | C112: Motar Cycle, Scooter | D112: Agriculture Tractor, LCV Mini Bus | E112: Three Wheeler (Auto) Axle Truck, Buses | F112: Tractor Trailor, Truck Trailor Units (3 Axle & MAV) | G112: Total Fast Vehicle | H112: Cycle | I112: Cycle Rickshaw | J112: Hand Cart | K112: Horse Drawn | L112: Bullock Corts | M112: Total Slow | N112: Grand Total (Nos.) | O112: Grand Total (PCU's)
A114: 0800 - 0900 | B114: =B8+B9+B10+B11 -> 622 | C114: =C8+C9+C10+C11 -> 648 | D114: =D8+D9+D10+D11 -> 8 | E114: =E8+E9+E10+E11 -> 34 | F114: =F8+F9+F10+F11 -> 10 | G114: =SUM(B114:F114) -> 1322 | H114: =H8+H9+H10+H11 -> 2 | I114: =I8+I9+I10+I11 -> 0 | J114: =J8+J9+J10+J11 -> 0 | K114: =K8+K9+K10+K11 -> 0 | L114: =L8+L9+L10+L11 -> 13 | M114: =SUM(H114:K114) -> 2 | N114: =G114+M114 -> 1324 | O114: =B114*1+C114*0.5+D114*1.5+E114*3+F114*4.5+H114*0.5+I114*1.5+J114*3+K114*4+L114*8 -> 1210
A115: 0815 - 0915 | B115: =B9+B10+B11+B12 -> 590 | C115: =C9+C10+C11+C12 -> 629 | D115: =D9+D10+D11+D12 -> 4 | E115: =E9+E10+E11+E12 -> 34 | F115: =F9+F10+F11+F12 -> 8 | G115: =SUM(B115:F115) -> 1265 | H115: =H9+H10+H11+H12 -> 0 | I115: =I9+I10+I11+I12 -> 0 | J115: =J9+J10+J11+J12 -> 0 | K115: =K9+K10+K11+K12 -> 0 | L115: =L9+L10+L11+L12 -> 11 | M115: =SUM(H115:K115) -> 0 | N115: =G115+M115 -> 1265 | O115: =B115*1+C115*0.5+D115*1.5+E115*3+F115*4.5+H115*0.5+I115*1.5+J115*3+K115*4+L115*8 -> 1136.5
A116: 0830 - 0930 | B116: =B10+B11+B12+B13 -> 550 | C116: =C10+C11+C12+C13 -> 608 | D116: =D10+D11+D12+D13 -> 5 | E116: =E10+E11+E12+E13 -> 32 | F116: =F10+F11+F12+F13 -> 8 | G116: =SUM(B116:F116) -> 1203 | H116: =H10+H11+H12+H13 -> 0 | I116: =I10+I11+I12+I13 -> 0 | J116: =J10+J11+J12+J13 -> 0 | K116: =K10+K11+K12+K13 -> 0 | L116: =L10+L11+L12+L13 -> 10 | M116: =SUM(H116:K116) -> 0 | N116: =G116+M116 -> 1203 | O116: =B116*1+C116*0.5+D116*1.5+E116*3+F116*4.5+H116*0.5+I116*1.5+J116*3+K116*4+L116*8 -> 1073.5
A117: 0845 - 0945 | B117: =B11+B12+B13+B14 -> 549 | C117: =C11+C12+C13+C14 -> 661 | D117: =D11+D12+D13+D14 -> 9 | E117: =E11+E12+E13+E14 -> 27 | F117: =F11+F12+F13+F14 -> 2 | G117: =SUM(B117:F117) -> 1248 | H117: =H11+H12+H13+H14 -> 0 | I117: =I11+I12+I13+I14 -> 0 | J117: =J11+J12+J13+J14 -> 0 | K117: =K11+K12+K13+K14 -> 0 | L117: =L11+L12+L13+L14 -> 13 | M117: =SUM(H117:K117) -> 0 | N117: =G117+M117 -> 1248 | O117: =B117*1+C117*0.5+D117*1.5+E117*3+F117*4.5+H117*0.5+I117*1.5+J117*3+K117*4+L117*8 -> 1087
A118: 0900 - 1000 | B118: =B12+B13+B14+B15 -> 626 | C118: =C12+C13+C14+C15 -> 693 | D118: =D12+D13+D14+D15 -> 14 | E118: =E12+E13+E14+E15 -> 42 | F118: =F12+F13+F14+F15 -> 3 | G118: =SUM(B118:F118) -> 1378 | H118: =H12+H13+H14+H15 -> 0 | I118: =I12+I13+I14+I15 -> 0 | J118: =J12+J13+J14+J15 -> 0 | K118: =K12+K13+K14+K15 -> 0 | L118: =L12+L13+L14+L15 -> 10 | M118: =SUM(H118:K118) -> 0 | N118: =G118+M118 -> 1378 | O118: =B118*1+C118*0.5+D118*1.5+E118*3+F118*4.5+H118*0.5+I118*1.5+J118*3+K118*4+L118*8 -> 1213
A119: 0915 - 1015 | B119: =B13+B14+B15+B16 -> 658 | C119: =C13+C14+C15+C16 -> 668 | D119: =D13+D14+D15+D16 -> 20 | E119: =E13+E14+E15+E16 -> 52 | F119: =F13+F14+F15+F16 -> 7 | G119: =SUM(B119:F119) -> 1405 | H119: =H13+H14+H15+H16 -> 0 | I119: =I13+I14+I15+I16 -> 0 | J119: =J13+J14+J15+J16 -> 0 | K119: =K13+K14+K15+K16 -> 0 | L119: =L13+L14+L15+L16 -> 7 | M119: =SUM(H119:K119) -> 0 | N119: =G119+M119 -> 1405 | O119: =B119*1+C119*0.5+D119*1.5+E119*3+F119*4.5+H119*0.5+I119*1.5+J119*3+K119*4+L119*8 -> 1265.5
A120: 0930 - 1030 | B120: =B14+B15+B16+B17 -> 707 | C120: =C14+C15+C16+C17 -> 628 | D120: =D14+D15+D16+D17 -> 25 | E120: =E14+E15+E16+E17 -> 61 | F120: =F14+F15+F16+F17 -> 12 | G120: =SUM(B120:F120) -> 1433 | H120: =H14+H15+H16+H17 -> 0 | I120: =I14+I15+I16+I17 -> 0 | J120: =J14+J15+J16+J17 -> 0 | K120: =K14+K15+K16+K17 -> 0 | L120: =L14+L15+L16+L17 -> 6 | M120: =SUM(H120:K120) -> 0 | N120: =G120+M120 -> 1433 | O120: =B120*1+C120*0.5+D120*1.5+E120*3+F120*4.5+H120*0.5+I120*1.5+J120*3+K120*4+L120*8 -> 1343.5
A121: 0945 - 1045 | B121: =B15+B16+B17+B18 -> 674 | C121: =C15+C16+C17+C18 -> 451 | D121: =D15+D16+D17+D18 -> 23 | E121: =E15+E16+E17+E18 -> 70 | F121: =F15+F16+F17+F18 -> 15 | G121: =SUM(B121:F121) -> 1233 | H121: =H15+H16+H17+H18 -> 0 | I121: =I15+I16+I17+I18 -> 0 | J121: =J15+J16+J17+J18 -> 0 | K121: =K15+K16+K17+K18 -> 0 | L121: =L15+L16+L17+L18 -> 2 | M121: =SUM(H121:K121) -> 0 | N121: =G121+M121 -> 1233 | O121: =B121*1+C121*0.5+D121*1.5+E121*3+F121*4.5+H121*0.5+I121*1.5+J121*3+K121*4+L121*8 -> 1227.5
A122: 1000 - 1100 | B122: =B16+B17+B18+B19 -> 637 | C122: =C16+C17+C18+C19 -> 338 | D122: =D16+D17+D18+D19 -> 21 | E122: =E16+E17+E18+E19 -> 60 | F122: =F16+F17+F18+F19 -> 16 | G122: =SUM(B122:F122) -> 1072 | H122: =H16+H17+H18+H19 -> 0 | I122: =I16+I17+I18+I19 -> 0 | J122: =J16+J17+J18+J19 -> 0 | K122: =K16+K17+K18+K19 -> 0 | L122: =L16+L17+L18+L19 -> 3 | M122: =SUM(H122:K122) -> 0 | N122: =G122+M122 -> 1072 | O122: =B122*1+C122*0.5+D122*1.5+E122*3+F122*4.5+H122*0.5+I122*1.5+J122*3+K122*4+L122*8 -> 1113.5
A123: 1015 - 1115 | B123: =B17+B18+B19+B20 -> 647 | C123: =C17+C18+C19+C20 -> 278 | D123: =D17+D18+D19+D20 -> 22 | E123: =E17+E18+E19+E20 -> 51 | F123: =F17+F18+F19+F20 -> 14 | G123: =SUM(B123:F123) -> 1012 | H123: =H17+H18+H19+H20 -> 0 | I123: =I17+I18+I19+I20 -> 0 | J123: =J17+J18+J19+J20 -> 0 | K123: =K17+K18+K19+K20 -> 0 | L123: =L17+L18+L19+L20 -> 3 | M123: =SUM(H123:K123) -> 0 | N123: =G123+M123 -> 1012 | O123: =B123*1+C123*0.5+D123*1.5+E123*3+F123*4.5+H123*0.5+I123*1.5+J123*3+K123*4+L123*8 -> 1059
A124: 1030 - 1130 | B124: =B18+B19+B20+B21 -> 641 | C124: =C18+C19+C20+C21 -> 333 | D124: =D18+D19+D20+D21 -> 18 | E124: =E18+E19+E20+E21 -> 50 | F124: =F18+F19+F20+F21 -> 12 | G124: =SUM(B124:F124) -> 1054 | H124: =H18+H19+H20+H21 -> 0 | I124: =I18+I19+I20+I21 -> 0 | J124: =J18+J19+J20+J21 -> 0 | K124: =K18+K19+K20+K21 -> 0 | L124: =L18+L19+L20+L21 -> 4 | M124: =SUM(H124:K124) -> 0 | N124: =G124+M124 -> 1054 | O124: =B124*1+C124*0.5+D124*1.5+E124*3+F124*4.5+H124*0.5+I124*1.5+J124*3+K124*4+L124*8 -> 1070.5
A125: 1045 - 1145 | B125: =B19+B20+B21+B22 -> 677 | C125: =C19+C20+C21+C22 -> 333 | D125: =D19+D20+D21+D22 -> 20 | E125: =E19+E20+E21+E22 -> 48 | F125: =F19+F20+F21+F22 -> 11 | G125: =SUM(B125:F125) -> 1089 | H125: =H19+H20+H21+H22 -> 0 | I125: =I19+I20+I21+I22 -> 0 | J125: =J19+J20+J21+J22 -> 0 | K125: =K19+K20+K21+K22 -> 0 | L125: =L19+L20+L21+L22 -> 4 | M125: =SUM(H125:K125) -> 0 | N125: =G125+M125 -> 1089 | O125: =B125*1+C125*0.5+D125*1.5+E125*3+F125*4.5+H125*0.5+I125*1.5+J125*3+K125*4+L125*8 -> 1099
... A206: 0745 - 0845 | B206: =B100+B101+B102+B103 -> 954 | C206: =C100+C101+C102+C103 -> 1922 | D206: =D100+D101+D102+D103 -> 8 | E206: =E100+E101+E102+E103 -> 22 | F206: =F100+F101+F102+F103 -> 4 | G206: =SUM(B206:F206) -> 2910 | H206: =H100+H101+H102+H103 -> 8 | I206: =I100+I101+I102+I103 -> 0 | J206: =J100+J101+J102+J103 -> 0 | K206: =K100+K101+K102+K103 -> 0 | L206: =L100+L101+L102+L103 -> 10 | M206: =SUM(H206:K206) -> 8 | N206: =G206+M206 -> 2918 | O206: =B206*1+C206*0.5+D206*1.5+E206*3+F206*4.5+H206*0.5+I206*1.5+J206*3+K206*4+L206*8 -> 2095

Sheet V_3
A1: CLASSIFIED TRAFFIC VOLUME COUNT AT INTERSECTION
A2: Location Name : | B2: =Summary!B2 -> TMC-14 Number (D2)
A3: Location Code : | B3: =Summary!B3 -> D2
A4: Direction From : | B4: =+Summary!A6 -> Nindar | D4: To: | E4: =Summary!F11 -> Mansarover
A6: Time | B6: Car, Taxi, Tempo, Auto Rickshaw & Pick up | C6: Motar Cycle, Scooter | D6: Agriculture Tractor, LCV Mini Bus | E6: Three Wheeler (Auto) Axle Truck, Buses | F6: Tractor Trailor, Truck Trailor Units (3 Axle & MAV) | G6: Total Fast Vehicle | H6: Cycle | I6: Cycle Rickshaw | J6: Hand Cart | K6: Horse Drawn | L6: Bullock Corts | M6: Total Slow | N6: Grand Total (Nos.) | O6: Grand Total (PCU's)
A8: 0800-0815 | B8: 130 | C8: 66 | D8: 6 | E8: 0 | F8: 9 | G8: =SUM(B8:F8) -> 211 | H8: 0 | I8: 0 | J8: 0 | K8: 0 | L8: 0 | M8: 1 | N8: =G8+M8 -> 212 | O8: =B8*1+C8*0.5+D8*1.5+E8*3+F8*4.5+H8*0.5+I8*1.5+J8*3+K8*4+L8*8 -> 212.5
A9: 0815-0830 | B9: 97 | C9: 104 | D9: 7 | E9: 1 | F9: 5 | G9: =SUM(B9:F9) -> 214 | H9: 1 | I9: 0 | J9: 0 | K9: 0 | L9: 0 | M9: 0 | N9: =G9+M9 -> 214 | O9: =B9*1+C9*0.5+D9*1.5+E9*3+F9*4.5+H9*0.5+I9*1.5+J9*3+K9*4+L9*8 -> 185.5
A10: 0830-0845 | B10: 87 | C10: 111 | D10: 6 | E10: 1 | F10: 7 | G10: =SUM(B10:F10) -> 212 | H10: 0 | I10: 0 | J10: 0 | K10: 0 | L10: 0 | M10: 0 | N10: =G10+M10 -> 212 | O10: =B10*1+C10*0.5+D10*1.5+E10*3+F10*4.5+H10*0.5+I10*1.5+J10*3+K10*4+L10*8 -> 186
A11: 0845-0900 | B11: 91 | C11: 60 | D11: 4 | E11: 0 | F11: 2 | G11: =SUM(B11:F11) -> 157 | H11: 0 | I11: 0 | J11: 0 | K11: 0 | L11: 0 | M11: 0 | N11: =G11+M11 -> 157 | O11: =B11*1+C11*0.5+D11*1.5+E11*3+F11*4.5+H11*0.5+I11*1.5+J11*3+K11*4+L11*8 -> 136
A12: 0900-0915 | B12: 95 | C12: 78 | D12: 3 | E12: 1 | F12: 8 | G12: =SUM(B12:F12) -> 185 | H12: 0 | I12: 0 | J12: 0 | K12: 0 | L12: 0 | M12: 0 | N12: =G12+M12 -> 185 | O12: =B12*1+C12*0.5+D12*1.5+E12*3+F12*4.5+H12*0.5+I12*1.5+J12*3+K12*4+L12*8 -> 177.5
A13: 0915-0930 | B13: 108 | C13: 86 | D13: 5 | E13: 1 | F13: 4 | G13: =SUM(B13:F13) -> 204 | H13: 0 | I13: 0 | J13: 0 | K13: 0 | L13: 0 | M13: 0 | N13: =G13+M13 -> 204 | O13: =B13*1+C13*0.5+D13*1.5+E13*3+F13*4.5+H13*0.5+I13*1.5+J13*3+K13*4+L13*8 -> 179.5
A14: 0930-0945 | B14: 125 | C14: 111 | D14: 2 | E14: 1 | F14: 5 | G14: =SUM(B14:F14) -> 244 | H14: 0 | I14: 0 | J14: 0 | K14: 0 | L14: 0 | M14: 0 | N14: =G14+M14 -> 244 | O14: =B14*1+C14*0.5+D14*1.5+E14*3+F14*4.5+H14*0.5+I14*1.5+J14*3+K14*4+L14*8 -> 209
A15: 0945-1000 | B15: 176 | C15: 94 | D15: 5 | E15: 1 | F15: 10 | G15: =SUM(B15:F15) -> 286 | H15: 0 | I15: 0 | J15: 0 | K15: 0 | L15: 0 | M15: 0 | N15: =G15+M15 -> 286 | O15: =B15*1+C15*0.5+D15*1.5+E15*3+F15*4.5+H15*0.5+I15*1.5+J15*3+K15*4+L15*8 -> 278.5
A16: 1000-1015 | B16: 116 | C16: 63 | D16: 4 | E16: 1 | F16: 6 | G16: =SUM(B16:F16) -> 190 | H16: 0 | I16: 0 | J16: 0 | K16: 0 | L16: 0 | M16: 0 | N16: =G16+M16 -> 190 | O16: =B16*1+C16*0.5+D16*1.5+E16*3+F16*4.5+H16*0.5+I16*1.5+J16*3+K16*4+L16*8 -> 183.5
A17: 1015-1030 | B17: 121 | C17: 72 | D17: 8 | E17: 0 | F17: 9 | G17: =SUM(B17:F17) -> 210 | H17: 0 | I17: 0 | J17: 0 | K17: 0 | L17: 0 | M17: 0 | N17: =G17+M17 -> 210 | O17: =B17*1+C17*0.5+D17*1.5+E17*3+F17*4.5+H17*0.5+I17*1.5+J17*3+K17*4+L17*8 -> 209.5
A18: 1030-1045 | B18: 105 | C18: 33 | D18: 4 | E18: 1 | F18: 7 | G18: =SUM(B18:F18) -> 150 | H18: 0 | I18: 0 | J18: 0 | K18: 0 | L18: 0 | M18: 0 | N18: =G18+M18 -> 150 | O18: =B18*1+C18*0.5+D18*1.5+E18*3+F18*4.5+H18*0.5+I18*1.5+J18*3+K18*4+L18*8 -> 162
A19: 1045-1100 | B19: 111 | C19: 33 | D19: 9 | E19: 1 | F19: 7 | G19: =SUM(B19:F19) -> 161 | H19: 0 | I19: 0 | J19: 0 | K19: 0 | L19: 0 | M19: 0 | N19: =G19+M19 -> 161 | O19: =B19*1+C19*0.5+D19*1.5+E19*3+F19*4.5+H19*0.5+I19*1.5+J19*3+K19*4+L19*8 -> 175.5
... A103: 0745-0800 | B103: 177 | C103: 45 | D103: 2 | E103: 1 | F103: 6 | G103: =SUM(B103:F103) -> 231 | H103: 0 | I103: 0 | J103: 0 | K103: 0 | L103: 0 | M103: 0 | N103: =G103+M103 -> 231 | O103: =B103*1+C103*0.5+D103*1.5+E103*3+F103*4.5+H103*0.5+I103*1.5+J103*3+K103*4+L103*8 -> 232.5
A104: Total (Veh.) | B104: =SUM(B8:B103) -> 6361 | C104: =SUM(C8:C103) -> 1717 | D104: =SUM(D8:D103) -> 357 | E104: =SUM(E8:E103) -> 114 | F104: =SUM(F8:F103) -> 548 | G104: =SUM(G8:G103) -> 9097 | H104: =SUM(H8:H103) -> 2 | I104: =SUM(I8:I103) -> 0 | ... O104: =SUM(O8:O103) -> 10572
A105: Total (PCUs) | B105: =+B104*1 -> 6361 | C105: =+C104*0.5 -> 858.5 | D105: =+D104*1.5 -> 535.5 | E105: =+E104*3 -> 342 | F105: =+F104*4.5 -> 2466 | G105: =SUM(B105:F105) -> 10563 | H105: =+H104*0.5 -> 1 | I105: =+I104*1.5 -> 0 | J105: =+J104*3 -> 0 | K105: =+K104*4 -> 0 | L105: =+L104*8 -> 8 | M105: =SUM(H105:L105) -> 9 | O105: =G105+M105 -> 10572
A106: Composition | B106: =B104/$N$104 -> 0.69901099 | C106: =C104/$N$104 -> 0.18868132 | D106: =D104/$N$104 -> 0.039230769 | E106: =E104/$N$104 -> 0.012527473 | F106: =F104/$N$104 -> 0.06021978 | G106: =G104/$N$104 -> 0.99967033 | H106: =H104/$N$104 -> 0.00021978022 | I106: =I104/$N$104 -> 0 | ... N106: =N104/$N$104 -> 1
A108: Location Name : | B108: =B2 -> TMC-14 Number (D2)
A109: Location Code : | B109: =B3 -> D2
A110: Direction From : | B110: =B4 -> Nindar | D110: =D4 -> To:
A112: Time | B112: Car, Taxi, Tempo, Auto Rickshaw & Pick up | C112: Motar Cycle, Scooter | D112: Agriculture Tractor, LCV Mini Bus | E112: Three Wheeler (Auto) Axle Truck, Buses | F112: Tractor Trailor, Truck Trailor Units (3 Axle & MAV) | G112: Total Fast Vehicle | H112: Cycle | I112: Cycle Rickshaw | J112: Hand Cart | K112: Horse Drawn | L112: Bullock Corts | M112: Total Slow | N112: Grand Total (Nos.) | O112: Grand Total (PCU's)
A114: 0800 - 0900 | B114: =B8+B9+B10+B11 -> 405 | C114: =C8+C9+C10+C11 -> 341 | D114: =D8+D9+D10+D11 -> 23 | E114: =E8+E9+E10+E11 -> 2 | F114: =F8+F9+F10+F11 -> 23 | G114: =SUM(B114:F114) -> 794 | H114: =H8+H9+H10+H11 -> 1 | I114: =I8+I9+I10+I11 -> 0 | J114: =J8+J9+J10+J11 -> 0 | K114: =K8+K9+K10+K11 -> 0 | L114: =L8+L9+L10+L11 -> 0 | M114: =SUM(H114:K114) -> 1 | N114: =G114+M114 -> 795 | O114: =B114*1+C114*0.5+D114*1.5+E114*3+F114*4.5+H114*0.5+I114*1.5+J114*3+K114*4+L114*8 -> 720
A115: 0815 - 0915 | B115: =B9+B10+B11+B12 -> 370 | C115: =C9+C10+C11+C12 -> 353 | D115: =D9+D10+D11+D12 -> 20 | E115: =E9+E10+E11+E12 -> 3 | F115: =F9+F10+F11+F12 -> 22 | G115: =SUM(B115:F115) -> 768 | H115: =H9+H10+H11+H12 -> 1 | I115: =I9+I10+I11+I12 -> 0 | J115: =J9+J10+J11+J12 -> 0 | K115: =K9+K10+K11+K12 -> 0 | L115: =L9+L10+L11+L12 -> 0 | M115: =SUM(H115:K115) -> 1 | N115: =G115+M115 -> 769 | O115: =B115*1+C115*0.5+D115*1.5+E115*3+F115*4.5+H115*0.5+I115*1.5+J115*3+K115*4+L115*8 -> 685
A116: 0830 - 0930 | B116: =B10+B11+B12+B13 -> 381 | C116: =C10+C11+C12+C13 -> 335 | D116: =D10+D11+D12+D13 -> 18 | E116: =E10+E11+E12+E13 -> 3 | F116: =F10+F11+F12+F13 -> 21 | G116: =SUM(B116:F116) -> 758 | H116: =H10+H11+H12+H13 -> 0 | I116: =I10+I11+I12+I13 -> 0 | J116: =J10+J11+J12+J13 -> 0 | K116: =K10+K11+K12+K13 -> 0 | L116: =L10+L11+L12+L13 -> 0 | M116: =SUM(H116:K116) -> 0 | N116: =G116+M116 -> 758 | O116: =B116*1+C116*0.5+D116*1.5+E116*3+F116*4.5+H116*0.5+I116*1.5+J116*3+K116*4+L116*8 -> 679
A117: 0845 - 0945 | B117: =B11+B12+B13+B14 -> 419 | C117: =C11+C12+C13+C14 -> 335 | D117: =D11+D12+D13+D14 -> 14 | E117: =E11+E12+E13+E14 -> 3 | F117: =F11+F12+F13+F14 -> 19 | G117: =SUM(B117:F117) -> 790 | H117: =H11+H12+H13+H14 -> 0 | I117: =I11+I12+I13+I14 -> 0 | J117: =J11+J12+J13+J14 -> 0 | K117: =K11+K12+K13+K14 -> 0 | L117: =L11+L12+L13+L14 -> 0 | M117: =SUM(H117:K117) -> 0 | N117: =G117+M117 -> 790 | O117: =B117*1+C117*0.5+D117*1.5+E117*3+F117*4.5+H117*0.5+I117*1.5+J117*3+K117*4+L117*8 -> 702
A118: 0900 - 1000 | B118: =B12+B13+B14+B15 -> 504 | C118: =C12+C13+C14+C15 -> 369 | D118: =D12+D13+D14+D15 -> 15 | E118: =E12+E13+E14+E15 -> 4 | F118: =F12+F13+F14+F15 -> 27 | G118: =SUM(B118:F118) -> 919 | H118: =H12+H13+H14+H15 -> 0 | I118: =I12+I13+I14+I15 -> 0 | J118: =J12+J13+J14+J15 -> 0 | K118: =K12+K13+K14+K15 -> 0 | L118: =L12+L13+L14+L15 -> 0 | M118: =SUM(H118:K118) -> 0 | N118: =G118+M118 -> 919 | O118: =B118*1+C118*0.5+D118*1.5+E118*3+F118*4.5+H118*0.5+I118*1.5+J118*3+K118*4+L118*8 -> 844.5
A119: 0915 - 1015 | B119: =B13+B14+B15+B16 -> 525 | C119: =C13+C14+C15+C16 -> 354 | D119: =D13+D14+D15+D16 -> 16 | E119: =E13+E14+E15+E16 -> 4 | F119: =F13+F14+F15+F16 -> 25 | G119: =SUM(B119:F119) -> 924 | H119: =H13+H14+H15+H16 -> 0 | I119: =I13+I14+I15+I16 -> 0 | J119: =J13+J14+J15+J16 -> 0 | K119: =K13+K14+K15+K16 -> 0 | L119: =L13+L14+L15+L16 -> 0 | M119: =SUM(H119:K119) -> 0 | N119: =G119+M119 -> 924 | O119: =B119*1+C119*0.5+D119*1.5+E119*3+F119*4.5+H119*0.5+I119*1.5+J119*3+K119*4+L119*8 -> 850.5
A120: 0930 - 1030 | B120: =B14+B15+B16+B17 -> 538 | C120: =C14+C15+C16+C17 -> 340 | D120: =D14+D15+D16+D17 -> 19 | E120: =E14+E15+E16+E17 -> 3 | F120: =F14+F15+F16+F17 -> 30 | G120: =SUM(B120:F120) -> 930 | H120: =H14+H15+H16+H17 -> 0 | I120: =I14+I15+I16+I17 -> 0 | J120: =J14+J15+J16+J17 -> 0 | K120: =K14+K15+K16+K17 -> 0 | L120: =L14+L15+L16+L17 -> 0 | M120: =SUM(H120:K120) -> 0 | N120: =G120+M120 -> 930 | O120: =B120*1+C120*0.5+D120*1.5+E120*3+F120*4.5+H120*0.5+I120*1.5+J120*3+K120*4+L120*8 -> 880.5
A121: 0945 - 1045 | B121: =B15+B16+B17+B18 -> 518 | C121: =C15+C16+C17+C18 -> 262 | D121: =D15+D16+D17+D18 -> 21 | E121: =E15+E16+E17+E18 -> 3 | F121: =F15+F16+F17+F18 -> 32 | G121: =SUM(B121:F121) -> 836 | H121: =H15+H16+H17+H18 -> 0 | I121: =I15+I16+I17+I18 -> 0 | J121: =J15+J16+J17+J18 -> 0 | K121: =K15+K16+K17+K18 -> 0 | L121: =L15+L16+L17+L18 -> 0 | M121: =SUM(H121:K121) -> 0 | N121: =G121+M121 -> 836 | O121: =B121*1+C121*0.5+D121*1.5+E121*3+F121*4.5+H121*0.5+I121*1.5+J121*3+K121*4+L121*8 -> 833.5
A122: 1000 - 1100 | B122: =B16+B17+B18+B19 -> 453 | C122: =C16+C17+C18+C19 -> 201 | D122: =D16+D17+D18+D19 -> 25 | E122: =E16+E17+E18+E19 -> 3 | F122: =F16+F17+F18+F19 -> 29 | G122: =SUM(B122:F122) -> 711 | H122: =H16+H17+H18+H19 -> 0 | I122: =I16+I17+I18+I19 -> 0 | J122: =J16+J17+J18+J19 -> 0 | K122: =K16+K17+K18+K19 -> 0 | L122: =L16+L17+L18+L19 -> 0 | M122: =SUM(H122:K122) -> 0 | N122: =G122+M122 -> 711 | O122: =B122*1+C122*0.5+D122*1.5+E122*3+F122*4.5+H122*0.5+I122*1.5+J122*3+K122*4+L122*8 -> 730.5
A123: 1015 - 1115 | B123: =B17+B18+B19+B20 -> 463 | C123: =C17+C18+C19+C20 -> 179 | D123: =D17+D18+D19+D20 -> 29 | E123: =E17+E18+E19+E20 -> 4 | F123: =F17+F18+F19+F20 -> 32 | G123: =SUM(B123:F123) -> 707 | H123: =H17+H18+H19+H20 -> 0 | I123: =I17+I18+I19+I20 -> 0 | J123: =J17+J18+J19+J20 -> 0 | K123: =K17+K18+K19+K20 -> 0 | L123: =L17+L18+L19+L20 -> 0 | M123: =SUM(H123:K123) -> 0 | N123: =G123+M123 -> 707 | O123: =B123*1+C123*0.5+D123*1.5+E123*3+F123*4.5+H123*0.5+I123*1.5+J123*3+K123*4+L123*8 -> 752
A124: 1030 - 1130 | B124: =B18+B19+B20+B21 -> 475 | C124: =C18+C19+C20+C21 -> 134 | D124: =D18+D19+D20+D21 -> 28 | E124: =E18+E19+E20+E21 -> 6 | F124: =F18+F19+F20+F21 -> 32 | G124: =SUM(B124:F124) -> 675 | H124: =H18+H19+H20+H21 -> 0 | I124: =I18+I19+I20+I21 -> 0 | J124: =J18+J19+J20+J21 -> 0 | K124: =K18+K19+K20+K21 -> 0 | L124: =L18+L19+L20+L21 -> 0 | M124: =SUM(H124:K124) -> 0 | N124: =G124+M124 -> 675 | O124: =B124*1+C124*0.5+D124*1.5+E124*3+F124*4.5+H124*0.5+I124*1.5+J124*3+K124*4+L124*8 -> 746
A125: 1045 - 1145 | B125: =B19+B20+B21+B22 -> 477 | C125: =C19+C20+C21+C22 -> 119 | D125: =D19+D20+D21+D22 -> 33 | E125: =E19+E20+E21+E22 -> 7 | F125: =F19+F20+F21+F22 -> 39 | G125: =SUM(B125:F125) -> 675 | H125: =H19+H20+H21+H22 -> 0 | I125: =I19+I20+I21+I22 -> 0 | J125: =J19+J20+J21+J22 -> 0 | K125: =K19+K20+K21+K22 -> 0 | L125: =L19+L20+L21+L22 -> 0 | M125: =SUM(H125:K125) -> 0 | N125: =G125+M125 -> 675 | O125: =B125*1+C125*0.5+D125*1.5+E125*3+F125*4.5+H125*0.5+I125*1.5+J125*3+K125*4+L125*8 -> 782.5
... A206: 0745 - 0845 | B206: =B100+B101+B102+B103 -> 565 | C206: =C100+C101+C102+C103 -> 122 | D206: =D100+D101+D102+D103 -> 11 | E206: =E100+E101+E102+E103 -> 4 | F206: =F100+F101+F102+F103 -> 14 | G206: =SUM(B206:F206) -> 716 | H206: =H100+H101+H102+H103 -> 1 | I206: =I100+I101+I102+I103 -> 0 | J206: =J100+J101+J102+J103 -> 0 | K206: =K100+K101+K102+K103 -> 0 | L206: =L100+L101+L102+L103 -> 0 | M206: =SUM(H206:K206) -> 1 | N206: =G206+M206 -> 717 | O206: =B206*1+C206*0.5+D206*1.5+E206*3+F206*4.5+H206*0.5+I206*1.5+J206*3+K206*4+L206*8 -> 718

Sheet V_4
A1: CLASSIFIED TRAFFIC VOLUME COUNT AT INTERSECTION
A2: Location Name : | B2: =Summary!B2 -> TMC-14 Number (D2)
A3: Location Code : | B3: =Summary!B3 -> D2
A4: Direction From : | B4: =Summary!J11 -> Delhi | D4: To: | E4: =Summary!H16 -> Chomu Pulia
A6: Time | B6: Car, Taxi, Tempo, Auto Rickshaw & Pick up | C6: Motar Cycle, Scooter | D6: Agriculture Tractor, LCV Mini Bus | E6: Three Wheeler (Auto) Axle Truck, Buses | F6: Tractor Trailor, Truck Trailor Units (3 Axle & MAV) | G6: Total Fast Vehicle | H6: Cycle | I6: Cycle Rickshaw | J6: Hand Cart | K6: Horse Drawn | L6: Bullock Corts | M6: Total Slow | N6: Grand Total (Nos.) | O6: Grand Total (PCU's)
A8: 0800-0815 | B8: 14 | C8: 25 | D8: 1 | E8: 1 | F8: 6 | G8: =SUM(B8:F8) -> 47 | H8: 0 | I8: 0 | J8: 0 | K8: 0 | L8: 1 | M8: 0 | N8: =G8+M8 -> 47 | O8: =B8*1+C8*0.5+D8*1.5+E8*3+F8*4.5+H8*0.5+I8*1.5+J8*3+K8*4+L8*8 -> 66
A9: 0815-0830 | B9: 15 | C9: 13 | D9: 1 | E9: 1 | F9: 4 | G9: =SUM(B9:F9) -> 34 | H9: 0 | I9: 0 | J9: 0 | K9: 0 | L9: 0 | M9: 0 | N9: =G9+M9 -> 34 | O9: =B9*1+C9*0.5+D9*1.5+E9*3+F9*4.5+H9*0.5+I9*1.5+J9*3+K9*4+L9*8 -> 44
A10: 0830-0845 | B10: 31 | C10: 51 | D10: 3 | E10: 2 | F10: 2 | G10: =SUM(B10:F10) -> 89 | H10: 0 | I10: 0 | J10: 0 | K10: 0 | L10: 2 | M10: 0 | N10: =G10+M10 -> 89 | O10: =B10*1+C10*0.5+D10*1.5+E10*3+F10*4.5+H10*0.5+I10*1.5+J10*3+K10*4+L10*8 -> 92
A11: 0845-0900 | B11: 30 | C11: 52 | D11: 1 | E11: 1 | F11: 3 | G11: =SUM(B11:F11) -> 87 | H11: 0 | I11: 0 | J11: 0 | K11: 0 | L11: 0 | M11: 0 | N11: =G11+M11 -> 87 | O11: =B11*1+C11*0.5+D11*1.5+E11*3+F11*4.5+H11*0.5+I11*1.5+J11*3+K11*4+L11*8 -> 74
A12: 0900-0915 | B12: 45 | C12: 59 | D12: 1 | E12: 2 | F12: 1 | G12: =SUM(B12:F12) -> 108 | H12: 1 | I12: 0 | J12: 0 | K12: 0 | L12: 2 | M12: 0 | N12: =G12+M12 -> 108 | O12: =B12*1+C12*0.5+D12*1.5+E12*3+F12*4.5+H12*0.5+I12*1.5+J12*3+K12*4+L12*8 -> 103
A13: 0915-0930 | B13: 44 | C13: 53 | D13: 3 | E13: 1 | F13: 6 | G13: =SUM(B13:F13) -> 107 | H13: 1 | I13: 0 | J13: 0 | K13: 0 | L13: 3 | M13: 0 | N13: =G13+M13 -> 107 | O13: =B13*1+C13*0.5+D13*1.5+E13*3+F13*4.5+H13*0.5+I13*1.5+J13*3+K13*4+L13*8 -> 129.5
A14: 0930-0945 | B14: 39 | C14: 51 | D14: 4 | E14: 0 | F14: 6 | G14: =SUM(B14:F14) -> 100 | H14: 0 | I14: 0 | J14: 0 | K14: 0 | L14: 7 | M14: 0 | N14: =G14+M14 -> 100 | O14: =B14*1+C14*0.5+D14*1.5+E14*3+F14*4.5+H14*0.5+I14*1.5+J14*3+K14*4+L14*8 -> 153.5
A15: 0945-1000 | B15: 41 | C15: 43 | D15: 6 | E15: 5 | F15: 0 | G15: =SUM(B15:F15) -> 95 | H15: 0 | I15: 0 | J15: 0 | K15: 0 | L15: 0 | M15: 0 | N15: =G15+M15 -> 95 | O15: =B15*1+C15*0.5+D15*1.5+E15*3+F15*4.5+H15*0.5+I15*1.5+J15*3+K15*4+L15*8 -> 86.5
A16: 1000-1015 | B16: 42 | C16: 35 | D16: 5 | E16: 1 | F16: 8 | G16: =SUM(B16:F16) -> 91 | H16: 0 | I16: 0 | J16: 0 | K16: 0 | L16: 0 | M16: 0 | N16: =G16+M16 -> 91 | O16: =B16*1+C16*0.5+D16*1.5+E16*3+F16*4.5+H16*0.5+I16*1.5+J16*3+K16*4+L16*8 -> 106
A17: 1015-1030 | B17: 40 | C17: 32 | D17: 5 | E17: 0 | F17: 0 | G17: =SUM(B17:F17) -> 77 | H17: 0 | I17: 0 | J17: 0 | K17: 0 | L17: 2 | M17: 0 | N17: =G17+M17 -> 77 | O17: =B17*1+C17*0.5+D17*1.5+E17*3+F17*4.5+H17*0.5+I17*1.5+J17*3+K17*4+L17*8 -> 79.5
A18: 1030-1045 | B18: 64 | C18: 37 | D18: 7 | E18: 0 | F18: 6 | G18: =SUM(B18:F18) -> 114 | H18: 0 | I18: 0 | J18: 0 | K18: 0 | L18: 2 | M18: 0 | N18: =G18+M18 -> 114 | O18: =B18*1+C18*0.5+D18*1.5+E18*3+F18*4.5+H18*0.5+I18*1.5+J18*3+K18*4+L18*8 -> 136
A19: 1045-1100 | B19: 56 | C19: 39 | D19: 7 | E19: 0 | F19: 0 | G19: =SUM(B19:F19) -> 102 | H19: 0 | I19: 0 | J19: 0 | K19: 0 | L19: 1 | M19: 0 | N19: =G19+M19 -> 102 | O19: =B19*1+C19*0.5+D19*1.5+E19*3+F19*4.5+H19*0.5+I19*1.5+J19*3+K19*4+L19*8 -> 94
... A103: 0745-0800 | B103: 20 | C103: 26 | D103: 1 | E103: 1 | F103: 3 | G103: =SUM(B103:F103) -> 51 | H103: 0 | I103: 0 | J103: 0 | K103: 0 | L103: 0 | M103: 0 | N103: =G103+M103 -> 51 | O103: =B103*1+C103*0.5+D103*1.5+E103*3+F103*4.5+H103*0.5+I103*1.5+J103*3+K103*4+L103*8 -> 51
A104: Total (Veh.) | B104: =SUM(B8:B103) -> 3037 | C104: =SUM(C8:C103) -> 1653 | D104: =SUM(D8:D103) -> 241 | E104: =SUM(E8:E103) -> 125 | F104: =SUM(F8:F103) -> 223 | G104: =SUM(G8:G103) -> 5279 | H104: =SUM(H8:H103) -> 4 | I104: =SUM(I8:I103) -> 0 | ... O104: =SUM(O8:O103) -> 6269.5
A105: Total (PCUs) | B105: =+B104*1 -> 3037 | C105: =+C104*0.5 -> 826.5 | D105: =+D104*1.5 -> 361.5 | E105: =+E104*3 -> 375 | F105: =+F104*4.5 -> 1003.5 | G105: =SUM(B105:F105) -> 5603.5 | H105: =+H104*0.5 -> 2 | I105: =+I104*1.5 -> 0 | J105: =+J104*3 -> 0 | K105: =+K104*4 -> 0 | L105: =+L104*8 -> 664 | M105: =SUM(H105:L105) -> 666 | O105: =G105+M105 -> 6269.5
A106: Composition | B106: =B104/$N$104 -> 0.57529835 | C106: =C104/$N$104 -> 0.31312749 | D106: =D104/$N$104 -> 0.045652586 | E106: =E104/$N$104 -> 0.023678727 | F106: =F104/$N$104 -> 0.042242849 | G106: =G104/$N$104 -> 1 | H106: =H104/$N$104 -> 0.00075771927 | I106: =I104/$N$104 -> 0 | ... N106: =N104/$N$104 -> 1
A108: Location Name : | B108: =B2 -> TMC-14 Number (D2)
A109: Location Code : | B109: =B3 -> D2
A110: Direction From : | B110: =B4 -> Delhi | D110: =D4 -> To:
A112: Time | B112: Car, Taxi, Tempo, Auto Rickshaw & Pick up | C112: Motar Cycle, Scooter | D112: Agriculture Tractor, LCV Mini Bus | E112: Three Wheeler (Auto) Axle Truck, Buses | F112: Tractor Trailor, Truck Trailor Units (3 Axle & MAV) | G112: Total Fast Vehicle | H112: Cycle | I112: Cycle Rickshaw | J112: Hand Cart | K112: Horse Drawn | L112: Bullock Corts | M112: Total Slow | N112: Grand Total (Nos.) | O112: Grand Total (PCU's)
A114: 0800 - 0900 | B114: =B8+B9+B10+B11 -> 90 | C114: =C8+C9+C10+C11 -> 141 | D114: =D8+D9+D10+D11 -> 6 | E114: =E8+E9+E10+E11 -> 5 | F114: =F8+F9+F10+F11 -> 15 | G114: =SUM(B114:F114) -> 257 | H114: =H8+H9+H10+H11 -> 0 | I114: =I8+I9+I10+I11 -> 0 | J114: =J8+J9+J10+J11 -> 0 | K114: =K8+K9+K10+K11 -> 0 | L114: =L8+L9+L10+L11 -> 3 | M114: =SUM(H114:K114) -> 0 | N114: =G114+M114 -> 257 | O114: =B114*1+C114*0.5+D114*1.5+E114*3+F114*4.5+H114*0.5+I114*1.5+J114*3+K114*4+L114*8 -> 276
A115: 0815 - 0915 | B115: =B9+B10+B11+B12 -> 121 | C115: =C9+C10+C11+C12 -> 175 | D115: =D9+D10+D11+D12 -> 6 | E115: =E9+E10+E11+E12 -> 6 | F115: =F9+F10+F11+F12 -> 10 | G115: =SUM(B115:F115) -> 318 | H115: =H9+H10+H11+H12 -> 1 | I115: =I9+I10+I11+I12 -> 0 | J115: =J9+J10+J11+J12 -> 0 | K115: =K9+K10+K11+K12 -> 0 | L115: =L9+L10+L11+L12 -> 4 | M115: =SUM(H115:K115) -> 1 | N115: =G115+M115 -> 319 | O115: =B115*1+C115*0.5+D115*1.5+E115*3+F115*4.5+H115*0.5+I115*1.5+J115*3+K115*4+L115*8 -> 313
A116: 0830 - 0930 | B116: =B10+B11+B12+B13 -> 150 | C116: =C10+C11+C12+C13 -> 215 | D116: =D10+D11+D12+D13 -> 8 | E116: =E10+E11+E12+E13 -> 6 | F116: =F10+F11+F12+F13 -> 12 | G116: =SUM(B116:F116) -> 391 | H116: =H10+H11+H12+H13 -> 2 | I116: =I10+I11+I12+I13 -> 0 | J116: =J10+J11+J12+J13 -> 0 | K116: =K10+K11+K12+K13 -> 0 | L116: =L10+L11+L12+L13 -> 7 | M116: =SUM(H116:K116) -> 2 | N116: =G116+M116 -> 393 | O116: =B116*1+C116*0.5+D116*1.5+E116*3+F116*4.5+H116*0.5+I116*1.5+J116*3+K116*4+L116*8 -> 398.5
A117: 0845 - 0945 | B117: =B11+B12+B13+B14 -> 158 | C117: =C11+C12+C13+C14 -> 215 | D117: =D11+D12+D13+D14 -> 9 | E117: =E11+E12+E13+E14 -> 4 | F117: =F11+F12+F13+F14 -> 16 | G117: =SUM(B117:F117) -> 402 | H117: =H11+H12+H13+H14 -> 2 | I117: =I11+I12+I13+I14 -> 0 | J117: =J11+J12+J13+J14 -> 0 | K117: =K11+K12+K13+K14 -> 0 | L117: =L11+L12+L13+L14 -> 12 | M117: =SUM(H117:K117) -> 2 | N117: =G117+M117 -> 404 | O117: =B117*1+C117*0.5+D117*1.5+E117*3+F117*4.5+H117*0.5+I117*1.5+J117*3+K117*4+L117*8 -> 460
A118: 0900 - 1000 | B118: =B12+B13+B14+B15 -> 169 | C118: =C12+C13+C14+C15 -> 206 | D118: =D12+D13+D14+D15 -> 14 | E118: =E12+E13+E14+E15 -> 8 | F118: =F12+F13+F14+F15 -> 13 | G118: =SUM(B118:F118) -> 410 | H118: =H12+H13+H14+H15 -> 2 | I118: =I12+I13+I14+I15 -> 0 | J118: =J12+J13+J14+J15 -> 0 | K118: =K12+K13+K14+K15 -> 0 | L118: =L12+L13+L14+L15 -> 12 | M118: =SUM(H118:K118) -> 2 | N118: =G118+M118 -> 412 | O118: =B118*1+C118*0.5+D118*1.5+E118*3+F118*4.5+H118*0.5+I118*1.5+J118*3+K118*4+L118*8 -> 472.5
A119: 0915 - 1015 | B119: =B13+B14+B15+B16 -> 166 | C119: =C13+C14+C15+C16 -> 182 | D119: =D13+D14+D15+D16 -> 18 | E119: =E13+E14+E15+E16 -> 7 | F119: =F13+F14+F15+F16 -> 20 | G119: =SUM(B119:F119) -> 393 | H119: =H13+H14+H15+H16 -> 1 | I119: =I13+I14+I15+I16 -> 0 | J119: =J13+J14+J15+J16 -> 0 | K119: =K13+K14+K15+K16 -> 0 | L119: =L13+L14+L15+L16 -> 10 | M119: =SUM(H119:K119) -> 1 | N119: =G119+M119 -> 394 | O119: =B119*1+C119*0.5+D119*1.5+E119*3+F119*4.5+H119*0.5+I119*1.5+J119*3+K119*4+L119*8 -> 475.5
A120: 0930 - 1030 | B120: =B14+B15+B16+B17 -> 162 | C120: =C14+C15+C16+C17 -> 161 | D120: =D14+D15+D16+D17 -> 20 | E120: =E14+E15+E16+E17 -> 6 | F120: =F14+F15+F16+F17 -> 14 | G120: =SUM(B120:F120) -> 363 | H120: =H14+H15+H16+H17 -> 0 | I120: =I14+I15+I16+I17 -> 0 | J120: =J14+J15+J16+J17 -> 0 | K120: =K14+K15+K16+K17 -> 0 | L120: =L14+L15+L16+L17 -> 9 | M120: =SUM(H120:K120) -> 0 | N120: =G120+M120 -> 363 | O120: =B120*1+C120*0.5+D120*1.5+E120*3+F120*4.5+H120*0.5+I120*1.5+J120*3+K120*4+L120*8 -> 425.5
A121: 0945 - 1045 | B121: =B15+B16+B17+B18 -> 187 | C121: =C15+C16+C17+C18 -> 147 | D121: =D15+D16+D17+D18 -> 23 | E121: =E15+E16+E17+E18 -> 6 | F121: =F15+F16+F17+F18 -> 14 | G121: =SUM(B121:F121) -> 377 | H121: =H15+H16+H17+H18 -> 0 | I121: =I15+I16+I17+I18 -> 0 | J121: =J15+J16+J17+J18 -> 0 | K121: =K15+K16+K17+K18 -> 0 | L121: =L15+L16+L17+L18 -> 4 | M121: =SUM(H121:K121) -> 0 | N121: =G121+M121 -> 377 | O121: =B121*1+C121*0.5+D121*1.5+E121*3+F121*4.5+H121*0.5+I121*1.5+J121*3+K121*4+L121*8 -> 408
A122: 1000 - 1100 | B122: =B16+B17+B18+B19 -> 202 | C122: =C16+C17+C18+C19 -> 143 | D122: =D16+D17+D18+D19 -> 24 | E122: =E16+E17+E18+E19 -> 1 | F122: =F16+F17+F18+F19 -> 14 | G122: =SUM(B122:F122) -> 384 | H122: =H16+H17+H18+H19 -> 0 | I122: =I16+I17+I18+I19 -> 0 | J122: =J16+J17+J18+J19 -> 0 | K122: =K16+K17+K18+K19 -> 0 | L122: =L16+L17+L18+L19 -> 5 | M122: =SUM(H122:K122) -> 0 | N122: =G122+M122 -> 384 | O122: =B122*1+C122*0.5+D122*1.5+E122*3+F122*4.5+H122*0.5+I122*1.5+J122*3+K122*4+L122*8 -> 415.5
A123: 1015 - 1115 | B123: =B17+B18+B19+B20 -> 211 | C123: =C17+C18+C19+C20 -> 132 | D123: =D17+D18+D19+D20 -> 25 | E123: =E17+E18+E19+E20 -> 3 | F123: =F17+F18+F19+F20 -> 9 | G123: =SUM(B123:F123) -> 380 | H123: =H17+H18+H19+H20 -> 0 | I123: =I17+I18+I19+I20 -> 0 | J123: =J17+J18+J19+J20 -> 0 | K123: =K17+K18+K19+K20 -> 0 | L123: =L17+L18+L19+L20 -> 6 | M123: =SUM(H123:K123) -> 0 | N123: =G123+M123 -> 380 | O123: =B123*1+C123*0.5+D123*1.5+E123*3+F123*4.5+H123*0.5+I123*1.5+J123*3+K123*4+L123*8 -> 412
A124: 1030 - 1130 | B124: =B18+B19+B20+B21 -> 223 | C124: =C18+C19+C20+C21 -> 127 | D124: =D18+D19+D20+D21 -> 28 | E124: =E18+E19+E20+E21 -> 3 | F124: =F18+F19+F20+F21 -> 9 | G124: =SUM(B124:F124) -> 390 | H124: =H18+H19+H20+H21 -> 0 | I124: =I18+I19+I20+I21 -> 0 | J124: =J18+J19+J20+J21 -> 0 | K124: =K18+K19+K20+K21 -> 0 | L124: =L18+L19+L20+L21 -> 6 | M124: =SUM(H124:K124) -> 0 | N124: =G124+M124 -> 390 | O124: =B124*1+C124*0.5+D124*1.5+E124*3+F124*4.5+H124*0.5+I124*1.5+J124*3+K124*4+L124*8 -> 426
A125: 1045 - 1145 | B125: =B19+B20+B21+B22 -> 206 | C125: =C19+C20+C21+C22 -> 120 | D125: =D19+D20+D21+D22 -> 23 | E125: =E19+E20+E21+E22 -> 5 | F125: =F19+F20+F21+F22 -> 6 | G125: =SUM(B125:F125) -> 360 | H125: =H19+H20+H21+H22 -> 0 | I125: =I19+I20+I21+I22 -> 0 | J125: =J19+J20+J21+J22 -> 0 | K125: =K19+K20+K21+K22 -> 0 | L125: =L19+L20+L21+L22 -> 5 | M125: =SUM(H125:K125) -> 0 | N125: =G125+M125 -> 360 | O125: =B125*1+C125*0.5+D125*1.5+E125*3+F125*4.5+H125*0.5+I125*1.5+J125*3+K125*4+L125*8 -> 382.5
... A206: 0745 - 0845 | B206: =B100+B101+B102+B103 -> 68 | C206: =C100+C101+C102+C103 -> 98 | D206: =D100+D101+D102+D103 -> 8 | E206: =E100+E101+E102+E103 -> 4 | F206: =F100+F101+F102+F103 -> 11 | G206: =SUM(B206:F206) -> 189 | H206: =H100+H101+H102+H103 -> 1 | I206: =I100+I101+I102+I103 -> 0 | J206: =J100+J101+J102+J103 -> 0 | K206: =K100+K101+K102+K103 -> 0 | L206: =L100+L101+L102+L103 -> 3 | M206: =SUM(H206:K206) -> 1 | N206: =G206+M206 -> 190 | O206: =B206*1+C206*0.5+D206*1.5+E206*3+F206*4.5+H206*0.5+I206*1.5+J206*3+K206*4+L206*8 -> 215

Sheet V_5
A1: CLASSIFIED TRAFFIC VOLUME COUNT AT INTERSECTION
A2: Location Name : | B2: =Summary!B2 -> TMC-14 Number (D2)
A3: Location Code : | B3: =Summary!B3 -> D2
A4: Direction From : | B4: =Summary!J11 -> Delhi | D4: To: | E4: =Summary!F11 -> Mansarover | G4: Flyover | H4: V5+V13
A6: Time | B6: Car, Taxi, Tempo, Auto Rickshaw & Pick up | C6: Motar Cycle, Scooter | D6: Agriculture Tractor, LCV Mini Bus | E6: Three Wheeler (Auto) Axle Truck, Buses | F6: Tractor Trailor, Truck Trailor Units (3 Axle & MAV) | G6: Total Fast Vehicle | H6: Cycle | I6: Cycle Rickshaw | J6: Hand Cart | K6: Horse Drawn | L6: Bullock Corts | M6: Total Slow | N6: Grand Total (Nos.) | O6: Grand Total (PCU's)
R7: Under Flyver
